Workbook
Name Item: #REF!

Sheet FORMULAS
A1: FORMULAS
A3: {=IFERROR(IF(J2="SET",MIN(_xlfn._xlws.FILTER($Z$2:$Z$563, ISNUMBER(MATCH(TRIM($A$2:$A$563), TRIM(_xlfn.TEXTSPLIT(I2, ",")), 0)))),ROUNDUP(Z2*0.8,0))+AA2,Z2)} -> 0 | F3: {=IFERROR(IF(#REF!="SET",IF(#REF!="Steak Set",ROUNDDOWN(MIN(_xlfn._xlws.FILTER($V$3:$V$562,ISNUMBER(MATCH(TRIM($A$3:$A$562),TRIM(_xlfn.TEXTSPLIT(#REF!,",")),0))))/4,0)+E3,IF(MIN(_xlfn._xlws.FILTER($V$3:$V$562,ISNUMBER(MATCH(TRIM($A$3:$A$562),TRIM(_xlfn.TEXTSPLIT(#REF!,",")),0))))>$L$1,MIN(_xlfn._xlws.FILTER($V$3:$V$562,ISNUMBER(MATCH(TRIM($A$3:$A$562),TRIM(_xlfn.TEXTSPLIT(#REF!,",")),0))))+E3,0+E3)),ROUNDUP(D3*0.9,0)+E3),ROUNDUP(D3*0.9,0)+E3)} -> 0
A5: =SUBSTITUTE(XLOOKUP(MID($A8,4,2),MID(#REF!,4,2),#REF!,0,0),"565","566")
F6: {=IFERROR(IF(#REF!="SET",IF(#REF!="Steak Set",ROUNDDOWN(MIN(_xlfn._xlws.FILTER($V$3:$V$562,ISNUMBER(MATCH(TRIM($A$3:$A$562),TRIM(_xlfn.TEXTSPLIT(#REF!,",")),0))))/4,0)+E6,IF(MIN(_xlfn._xlws.FILTER($V$3:$V$562,ISNUMBER(MATCH(TRIM($A$3:$A$562),TRIM(_xlfn.TEXTSPLIT(#REF!,",")),0))))>$L$1,MIN(_xlfn._xlws.FILTER($V$3:$V$562,ISNUMBER(MATCH(TRIM($A$3:$A$562),TRIM(_xlfn.TEXTSPLIT(#REF!,",")),0))))+E6,0+E6)),ROUNDUP(D6*0.9,0)+E6),ROUNDUP(D6*0.9,0)+E6)} -> 0

Sheet INSTRUCTIONS 
A1: Steps to update the OOS sheet
A3: 1) Download data from Woocom with the fields - Item, SKU, Stock (For ex, file name is "U1")
A4: 2) In the OOS template file, copy paste the fields - Date, Actual, Adj to three new columns
A5: - Change date to the current date
A6: 4) Use vlookup to update corresponding values from U1 to OOS template file on the particular date
A7: 5) Sort items based on stock count - smallest to largest
A8: 6) Filter the data to purchased goods (send to Alex) and to manufactured goods
A9: 7) Print the sheet and get actual count of the item
A10: 8) Input the numbers back to the sheet in the "actual" column
A11: 9) Determine the adjusted stock count to be updated on the website. Copy paste the formula used in previous day's adjusted column
A12: 10) Vlookup the adjusted values back to U1 file and upload to the website
A13: - save in CSV format and keep it plain (without any formatting)
... A23: Upload SKU and stock columns in a separate csv file

Sheet INVENTORY
D1: MIN QTY | E1: 2 | T1: 5
A2: SKU | B2: SKU | C2: DOW | D2: EA/ SET | E2: M / P | F2: Disco (Latest) | G2: Note | H2: DESCRIPTION | I2: turner | J2: CATEGORY | K2: DIVISON | L2: FAMILY | M2: SELECT | N2: CONTAINS | O2: Inventory | P2: Ready Sets | Q2: Stock (To upload on website) | T2: LOW STOCK
A3: 5005 | B3: 05005 | C3: FRI | D3: EA | E3: P | H3: TreeSpirit™ Individual 7.5" Solid Wood Salad Bowls - Walnut | I3: =ISNUMBER(SEARCH($I$2,H3)) -> FALSE | J3: TreeSpirit™ | K3: Utensils | L3: Utensils | O3: 9 | P3: {=_xlfn.XLOOKUP(TRIM(B3),TRIM('[1]wc-product-export-16-3-2026-177'!$A:$A),'[1]wc-product-export-16-3-2026-177'!$D:$D,0,0)} -> 0 | Q3: {=IF(TRIM($D3)="SET",IF($K3="Steak Set1",ROUNDDOWN(IFERROR(MIN(_xlfn._xlws.FILTER(O$3:O$650,ISNUMBER(MATCH(TRIM($B$3:$B$650),TRIM(_xlfn.TEXTSPLIT($N3,",")),0)))),0)/4,0)+P3,IF(IFERROR(MIN(_xlfn._xlws.FILTER(O$3:O$650,ISNUMBER(MATCH(TRIM($B$3:$B$650),TRIM(_xlfn.TEXTSPLIT($N3,",")),0)))),0)>=$E$1,IFERROR(MIN(_xlfn._xlws.FILTER(O$3:O$650,ISNUMBER(MATCH(TRIM($B$3:$B$650),TRIM(_xlfn.TEXTSPLIT($N3,",")),0)))),0)+P3,P3)),IF(TRIM($D3)="EA",IF(TRIM($E3)="M",ROUNDUP(O3*0.85,0),IF(TRIM($E3)="P",O3,P3)),P3))} -> 9 | T3: {=IFERROR(IF(D3="SET",_xlfn.TEXTJOIN(", ",TRUE,_xlfn._xlws.FILTER(TRANSPOSE(TRIM(_xlfn.TEXTSPLIT(N3,","))),COUNTIFS(B$3:B$650,TRANSPOSE(TRIM(_xlfn.TEXTSPLIT(N3,","))),O$3:O$650,"<="&$T$1))),""),"")}
A4: 5006 | B4: 05006 | C4: FRI | D4: EA | E4: P | H4: TreeSpirit™ Individual 7.5" Solid Wood Salad Bowls - Cherry | I4: =ISNUMBER(SEARCH($I$2,H4)) -> FALSE | J4: TreeSpirit™ | K4: Utensils | L4: Utensils | O4: 17 | P4: {=_xlfn.XLOOKUP(TRIM(B4),TRIM('[1]wc-product-export-16-3-2026-177'!$A:$A),'[1]wc-product-export-16-3-2026-177'!$D:$D,0,0)} -> 0 | Q4: {=IF(TRIM($D4)="SET",IF($K4="Steak Set1",ROUNDDOWN(IFERROR(MIN(_xlfn._xlws.FILTER(O$3:O$650,ISNUMBER(MATCH(TRIM($B$3:$B$650),TRIM(_xlfn.TEXTSPLIT($N4,",")),0)))),0)/4,0)+P4,IF(IFERROR(MIN(_xlfn._xlws.FILTER(O$3:O$650,ISNUMBER(MATCH(TRIM($B$3:$B$650),TRIM(_xlfn.TEXTSPLIT($N4,",")),0)))),0)>=$E$1,IFERROR(MIN(_xlfn._xlws.FILTER(O$3:O$650,ISNUMBER(MATCH(TRIM($B$3:$B$650),TRIM(_xlfn.TEXTSPLIT($N4,",")),0)))),0)+P4,P4)),IF(TRIM($D4)="EA",IF(TRIM($E4)="M",ROUNDUP(O4*0.85,0),IF(TRIM($E4)="P",O4,P4)),P4))} -> 17 | T4: {=IFERROR(IF(D4="SET",_xlfn.TEXTJOIN(", ",TRUE,_xlfn._xlws.FILTER(TRANSPOSE(TRIM(_xlfn.TEXTSPLIT(N4,","))),COUNTIFS(B$3:B$650,TRANSPOSE(TRIM(_xlfn.TEXTSPLIT(N4,","))),O$3:O$650,"<="&$T$1))),""),"")}
A5: 5013 | B5: 05013 | C5: FRI | D5: EA | E5: P | H5: TreeSpirit™ Individual 9" Solid Wood Salad Bowls - Walnut | I5: =ISNUMBER(SEARCH($I$2,H5)) -> FALSE | J5: TreeSpirit™ | K5: Utensils | L5: Utensils | O5: 16 | P5: {=_xlfn.XLOOKUP(TRIM(B5),TRIM('[1]wc-product-export-16-3-2026-177'!$A:$A),'[1]wc-product-export-16-3-2026-177'!$D:$D,0,0)} -> 0 | Q5: {=IF(TRIM($D5)="SET",IF($K5="Steak Set1",ROUNDDOWN(IFERROR(MIN(_xlfn._xlws.FILTER(O$3:O$650,ISNUMBER(MATCH(TRIM($B$3:$B$650),TRIM(_xlfn.TEXTSPLIT($N5,",")),0)))),0)/4,0)+P5,IF(IFERROR(MIN(_xlfn._xlws.FILTER(O$3:O$650,ISNUMBER(MATCH(TRIM($B$3:$B$650),TRIM(_xlfn.TEXTSPLIT($N5,",")),0)))),0)>=$E$1,IFERROR(MIN(_xlfn._xlws.FILTER(O$3:O$650,ISNUMBER(MATCH(TRIM($B$3:$B$650),TRIM(_xlfn.TEXTSPLIT($N5,",")),0)))),0)+P5,P5)),IF(TRIM($D5)="EA",IF(TRIM($E5)="M",ROUNDUP(O5*0.85,0),IF(TRIM($E5)="P",O5,P5)),P5))} -> 16 | T5: {=IFERROR(IF(D5="SET",_xlfn.TEXTJOIN(", ",TRUE,_xlfn._xlws.FILTER(TRANSPOSE(TRIM(_xlfn.TEXTSPLIT(N5,","))),COUNTIFS(B$3:B$650,TRANSPOSE(TRIM(_xlfn.TEXTSPLIT(N5,","))),O$3:O$650,"<="&$T$1))),""),"")}
B6: 02020 | C6: FRI | D6: EA | E6: P | H6: TS 2" MAPLE CONDIMENT CUP BULK | I6: =ISNUMBER(SEARCH($I$2,H6)) -> FALSE | J6: TreeSpirit™ | K6: Utensils | L6: Utensils | O6: N/A | P6: {=_xlfn.XLOOKUP(TRIM(B6),TRIM('[1]wc-product-export-16-3-2026-177'!$A:$A),'[1]wc-product-export-16-3-2026-177'!$D:$D,0,0)} -> 0 | T6: {=IFERROR(IF(D6="SET",_xlfn.TEXTJOIN(", ",TRUE,_xlfn._xlws.FILTER(TRANSPOSE(TRIM(_xlfn.TEXTSPLIT(N6,","))),COUNTIFS(B$3:B$650,TRANSPOSE(TRIM(_xlfn.TEXTSPLIT(N6,","))),O$3:O$650,"<="&$T$1))),""),"")}
A7: 5050 | B7: 05050 | C7: FRI | D7: EA | E7: M | H7: TreeSpirit™ Beekeeper's Gold 8 fl oz tub | I7: =ISNUMBER(SEARCH($I$2,H7)) -> FALSE | J7: TreeSpirit™ | K7: Protection | L7: Protection | O7: 16 | P7: {=_xlfn.XLOOKUP(TRIM(B7),TRIM('[1]wc-product-export-16-3-2026-177'!$A:$A),'[1]wc-product-export-16-3-2026-177'!$D:$D,0,0)} -> 0 | Q7: {=IF(TRIM($D7)="SET",IF($K7="Steak Set1",ROUNDDOWN(IFERROR(MIN(_xlfn._xlws.FILTER(O$3:O$650,ISNUMBER(MATCH(TRIM($B$3:$B$650),TRIM(_xlfn.TEXTSPLIT($N7,",")),0)))),0)/4,0)+P7,IF(IFERROR(MIN(_xlfn._xlws.FILTER(O$3:O$650,ISNUMBER(MATCH(TRIM($B$3:$B$650),TRIM(_xlfn.TEXTSPLIT($N7,",")),0)))),0)>=$E$1,IFERROR(MIN(_xlfn._xlws.FILTER(O$3:O$650,ISNUMBER(MATCH(TRIM($B$3:$B$650),TRIM(_xlfn.TEXTSPLIT($N7,",")),0)))),0)+P7,P7)),IF(TRIM($D7)="EA",IF(TRIM($E7)="M",ROUNDUP(O7*0.85,0),IF(TRIM($E7)="P",O7,P7)),P7))} -> 14 | T7: {=IFERROR(IF(D7="SET",_xlfn.TEXTJOIN(", ",TRUE,_xlfn._xlws.FILTER(TRANSPOSE(TRIM(_xlfn.TEXTSPLIT(N7,","))),COUNTIFS(B$3:B$650,TRANSPOSE(TRIM(_xlfn.TEXTSPLIT(N7,","))),O$3:O$650,"<="&$T$1))),""),"")}
A8: 5072 | B8: 05072 | C8: FRI | D8: SET | E8: M | F8: X | H8: Leather & Wood Preservation Set (Beekeeper's Gold & 8 oz Mineral Oil) | I8: =ISNUMBER(SEARCH($I$2,H8)) -> FALSE | J8: TreeSpirit™ | K8: Protection | L8: Protection | N8: 05050,05099 | O8: 18 | P8: {=_xlfn.XLOOKUP(TRIM(B8),TRIM('[1]wc-product-export-16-3-2026-177'!$A:$A),'[1]wc-product-export-16-3-2026-177'!$D:$D,0,0)} -> 0 | Q8: {=IF(TRIM($D8)="SET",IF($K8="Steak Set1",ROUNDDOWN(IFERROR(MIN(_xlfn._xlws.FILTER(O$3:O$650,ISNUMBER(MATCH(TRIM($B$3:$B$650),TRIM(_xlfn.TEXTSPLIT($N8,",")),0)))),0)/4,0)+P8,IF(IFERROR(MIN(_xlfn._xlws.FILTER(O$3:O$650,ISNUMBER(MATCH(TRIM($B$3:$B$650),TRIM(_xlfn.TEXTSPLIT($N8,",")),0)))),0)>=$E$1,IFERROR(MIN(_xlfn._xlws.FILTER(O$3:O$650,ISNUMBER(MATCH(TRIM($B$3:$B$650),TRIM(_xlfn.TEXTSPLIT($N8,",")),0)))),0)+P8,P8)),IF(TRIM($D8)="EA",IF(TRIM($E8)="M",ROUNDUP(O8*0.85,0),IF(TRIM($E8)="P",O8,P8)),P8))} -> 16 | T8: {=IFERROR(IF(D8="SET",_xlfn.TEXTJOIN(", ",TRUE,_xlfn._xlws.FILTER(TRANSPOSE(TRIM(_xlfn.TEXTSPLIT(N8,","))),COUNTIFS(B$3:B$650,TRANSPOSE(TRIM(_xlfn.TEXTSPLIT(N8,","))),O$3:O$650,"<="&$T$1))),""),"")}
B9: 05073 | C9: FRI | D9: SET | E9: M | H9: Beekeeper's Gold and 12 oz Mineral Oil - Wood and Leather Preservation Set | I9: =ISNUMBER(SEARCH($I$2,H9)) -> FALSE | J9: TreeSpirit™ | K9: Protection | L9: Protection | N9: 05050,05097 | O9: 16 | P9: {=_xlfn.XLOOKUP(TRIM(B9),TRIM('[1]wc-product-export-16-3-2026-177'!$A:$A),'[1]wc-product-export-16-3-2026-177'!$D:$D,0,0)} -> 0 | Q9: {=IF(TRIM($D9)="SET",IF($K9="Steak Set1",ROUNDDOWN(IFERROR(MIN(_xlfn._xlws.FILTER(O$3:O$650,ISNUMBER(MATCH(TRIM($B$3:$B$650),TRIM(_xlfn.TEXTSPLIT($N9,",")),0)))),0)/4,0)+P9,IF(IFERROR(MIN(_xlfn._xlws.FILTER(O$3:O$650,ISNUMBER(MATCH(TRIM($B$3:$B$650),TRIM(_xlfn.TEXTSPLIT($N9,",")),0)))),0)>=$E$1,IFERROR(MIN(_xlfn._xlws.FILTER(O$3:O$650,ISNUMBER(MATCH(TRIM($B$3:$B$650),TRIM(_xlfn.TEXTSPLIT($N9,",")),0)))),0)+P9,P9)),IF(TRIM($D9)="EA",IF(TRIM($E9)="M",ROUNDUP(O9*0.85,0),IF(TRIM($E9)="P",O9,P9)),P9))} -> 16 | T9: {=IFERROR(IF(D9="SET",_xlfn.TEXTJOIN(", ",TRUE,_xlfn._xlws.FILTER(TRANSPOSE(TRIM(_xlfn.TEXTSPLIT(N9,","))),COUNTIFS(B$3:B$650,TRANSPOSE(TRIM(_xlfn.TEXTSPLIT(N9,","))),O$3:O$650,"<="&$T$1))),""),"")}
A10: 20000 | B10: 20000 | C10: FRI | D10: EA | E10: M | F10: Z | H10: TT 3" SPATULA-FLEX, CG | I10: =ISNUMBER(SEARCH($I$2,H10)) -> FALSE | J10: Trade Tools | K10: Trade Tools | L10: Trade Tools | O10: N/A | P10: {=_xlfn.XLOOKUP(TRIM(B10),TRIM('[1]wc-product-export-16-3-2026-177'!$A:$A),'[1]wc-product-export-16-3-2026-177'!$D:$D,0,0)} -> 0 | Q10: {=IF(TRIM($D10)="SET",IF($K10="Steak Set1",ROUNDDOWN(IFERROR(MIN(_xlfn._xlws.FILTER(O$3:O$650,ISNUMBER(MATCH(TRIM($B$3:$B$650),TRIM(_xlfn.TEXTSPLIT($N10,",")),0)))),0)/4,0)+P10,IF(IFERROR(MIN(_xlfn._xlws.FILTER(O$3:O$650,ISNUMBER(MATCH(TRIM($B$3:$B$650),TRIM(_xlfn.TEXTSPLIT($N10,",")),0)))),0)>=$E$1,IFERROR(MIN(_xlfn._xlws.FILTER(O$3:O$650,ISNUMBER(MATCH(TRIM($B$3:$B$650),TRIM(_xlfn.TEXTSPLIT($N10,",")),0)))),0)+P10,P10)),IF(TRIM($D10)="EA",IF(TRIM($E10)="M",ROUNDUP(O10*0.85,0),IF(TRIM($E10)="P",O10,P10)),P10))} -> #VALUE! | T10: {=IFERROR(IF(D10="SET",_xlfn.TEXTJOIN(", ",TRUE,_xlfn._xlws.FILTER(TRANSPOSE(TRIM(_xlfn.TEXTSPLIT(N10,","))),COUNTIFS(B$3:B$650,TRANSPOSE(TRIM(_xlfn.TEXTSPLIT(N10,","))),O$3:O$650,"<="&$T$1))),""),"")}
A11: 20020 | B11: 20020 | C11: FRI | D11: EA | E11: M | H11: TT 4" SPATULA-FLEX, CG | I11: =ISNUMBER(SEARCH($I$2,H11)) -> FALSE | J11: Trade Tools | K11: Trade Tools | L11: Trade Tools | O11: N/A | P11: {=_xlfn.XLOOKUP(TRIM(B11),TRIM('[1]wc-product-export-16-3-2026-177'!$A:$A),'[1]wc-product-export-16-3-2026-177'!$D:$D,0,0)} -> 0 | Q11: {=IF(TRIM($D11)="SET",IF($K11="Steak Set1",ROUNDDOWN(IFERROR(MIN(_xlfn._xlws.FILTER(O$3:O$650,ISNUMBER(MATCH(TRIM($B$3:$B$650),TRIM(_xlfn.TEXTSPLIT($N11,",")),0)))),0)/4,0)+P11,IF(IFERROR(MIN(_xlfn._xlws.FILTER(O$3:O$650,ISNUMBER(MATCH(TRIM($B$3:$B$650),TRIM(_xlfn.TEXTSPLIT($N11,",")),0)))),0)>=$E$1,IFERROR(MIN(_xlfn._xlws.FILTER(O$3:O$650,ISNUMBER(MATCH(TRIM($B$3:$B$650),TRIM(_xlfn.TEXTSPLIT($N11,",")),0)))),0)+P11,P11)),IF(TRIM($D11)="EA",IF(TRIM($E11)="M",ROUNDUP(O11*0.85,0),IF(TRIM($E11)="P",O11,P11)),P11))} -> #VALUE! | T11: {=IFERROR(IF(D11="SET",_xlfn.TEXTJOIN(", ",TRUE,_xlfn._xlws.FILTER(TRANSPOSE(TRIM(_xlfn.TEXTSPLIT(N11,","))),COUNTIFS(B$3:B$650,TRANSPOSE(TRIM(_xlfn.TEXTSPLIT(N11,","))),O$3:O$650,"<="&$T$1))),""),"")}
A12: 5044 | B12: 05044 | C12: FRI | D12: SET | E12: P | H12: TreeSpirit™ 2-Piece Salad Server Sets - Maple 12" | I12: =ISNUMBER(SEARCH($I$2,H12)) -> FALSE | J12: TreeSpirit™ | K12: Utensils | L12: Utensils | O12: N/A | P12: {=_xlfn.XLOOKUP(TRIM(B12),TRIM('[1]wc-product-export-16-3-2026-177'!$A:$A),'[1]wc-product-export-16-3-2026-177'!$D:$D,0,0)} -> 0 | Q12: {=IF(TRIM($D12)="SET",IF($K12="Steak Set1",ROUNDDOWN(IFERROR(MIN(_xlfn._xlws.FILTER(O$3:O$650,ISNUMBER(MATCH(TRIM($B$3:$B$650),TRIM(_xlfn.TEXTSPLIT($N12,",")),0)))),0)/4,0)+P12,IF(IFERROR(MIN(_xlfn._xlws.FILTER(O$3:O$650,ISNUMBER(MATCH(TRIM($B$3:$B$650),TRIM(_xlfn.TEXTSPLIT($N12,",")),0)))),0)>=$E$1,IFERROR(MIN(_xlfn._xlws.FILTER(O$3:O$650,ISNUMBER(MATCH(TRIM($B$3:$B$650),TRIM(_xlfn.TEXTSPLIT($N12,",")),0)))),0)+P12,P12)),IF(TRIM($D12)="EA",IF(TRIM($E12)="M",ROUNDUP(O12*0.85,0),IF(TRIM($E12)="P",O12,P12)),P12))} -> 0 | T12: {=IFERROR(IF(D12="SET",_xlfn.TEXTJOIN(", ",TRUE,_xlfn._xlws.FILTER(TRANSPOSE(TRIM(_xlfn.TEXTSPLIT(N12,","))),COUNTIFS(B$3:B$650,TRANSPOSE(TRIM(_xlfn.TEXTSPLIT(N12,","))),O$3:O$650,"<="&$T$1))),""),"")}
A13: 5047 | B13: 05047 | C13: FRI | D13: SET | E13: P | F13: X | H13: TreeSpirit™ 2-Piece Salad Server Sets - Maple 14" | I13: =ISNUMBER(SEARCH($I$2,H13)) -> FALSE | J13: TreeSpirit™ | K13: Utensils | L13: Utensils | O13: N/A | P13: {=_xlfn.XLOOKUP(TRIM(B13),TRIM('[1]wc-product-export-16-3-2026-177'!$A:$A),'[1]wc-product-export-16-3-2026-177'!$D:$D,0,0)} -> 0 | Q13: {=IF(TRIM($D13)="SET",IF($K13="Steak Set1",ROUNDDOWN(IFERROR(MIN(_xlfn._xlws.FILTER(O$3:O$650,ISNUMBER(MATCH(TRIM($B$3:$B$650),TRIM(_xlfn.TEXTSPLIT($N13,",")),0)))),0)/4,0)+P13,IF(IFERROR(MIN(_xlfn._xlws.FILTER(O$3:O$650,ISNUMBER(MATCH(TRIM($B$3:$B$650),TRIM(_xlfn.TEXTSPLIT($N13,",")),0)))),0)>=$E$1,IFERROR(MIN(_xlfn._xlws.FILTER(O$3:O$650,ISNUMBER(MATCH(TRIM($B$3:$B$650),TRIM(_xlfn.TEXTSPLIT($N13,",")),0)))),0)+P13,P13)),IF(TRIM($D13)="EA",IF(TRIM($E13)="M",ROUNDUP(O13*0.85,0),IF(TRIM($E13)="P",O13,P13)),P13))} -> 0 | T13: {=IFERROR(IF(D13="SET",_xlfn.TEXTJOIN(", ",TRUE,_xlfn._xlws.FILTER(TRANSPOSE(TRIM(_xlfn.TEXTSPLIT(N13,","))),COUNTIFS(B$3:B$650,TRANSPOSE(TRIM(_xlfn.TEXTSPLIT(N13,","))),O$3:O$650,"<="&$T$1))),""),"")}
A14: 20040 | B14: 20040 | C14: FRI | D14: EA | E14: M | F14: Z | H14: TT 5" SPATULA-FLEX, CG | I14: =ISNUMBER(SEARCH($I$2,H14)) -> FALSE | J14: Trade Tools | K14: Trade Tools | L14: Trade Tools | O14: N/A | P14: {=_xlfn.XLOOKUP(TRIM(B14),TRIM('[1]wc-product-export-16-3-2026-177'!$A:$A),'[1]wc-product-export-16-3-2026-177'!$D:$D,0,0)} -> 0 | Q14: {=IF(TRIM($D14)="SET",IF($K14="Steak Set1",ROUNDDOWN(IFERROR(MIN(_xlfn._xlws.FILTER(O$3:O$650,ISNUMBER(MATCH(TRIM($B$3:$B$650),TRIM(_xlfn.TEXTSPLIT($N14,",")),0)))),0)/4,0)+P14,IF(IFERROR(MIN(_xlfn._xlws.FILTER(O$3:O$650,ISNUMBER(MATCH(TRIM($B$3:$B$650),TRIM(_xlfn.TEXTSPLIT($N14,",")),0)))),0)>=$E$1,IFERROR(MIN(_xlfn._xlws.FILTER(O$3:O$650,ISNUMBER(MATCH(TRIM($B$3:$B$650),TRIM(_xlfn.TEXTSPLIT($N14,",")),0)))),0)+P14,P14)),IF(TRIM($D14)="EA",IF(TRIM($E14)="M",ROUNDUP(O14*0.85,0),IF(TRIM($E14)="P",O14,P14)),P14))} -> #VALUE! | T14: {=IFERROR(IF(D14="SET",_xlfn.TEXTJOIN(", ",TRUE,_xlfn._xlws.FILTER(TRANSPOSE(TRIM(_xlfn.TEXTSPLIT(N14,","))),COUNTIFS(B$3:B$650,TRANSPOSE(TRIM(_xlfn.TEXTSPLIT(N14,","))),O$3:O$650,"<="&$T$1))),""),"")}
A15: 20060 | B15: 20060 | C15: FRI | D15: EA | E15: M | H15: TT 6" SPATULA-FLEX, CG | I15: =ISNUMBER(SEARCH($I$2,H15)) -> FALSE | J15: Trade Tools | K15: Trade Tools | L15: Trade Tools | O15: N/A | P15: {=_xlfn.XLOOKUP(TRIM(B15),TRIM('[1]wc-product-export-16-3-2026-177'!$A:$A),'[1]wc-product-export-16-3-2026-177'!$D:$D,0,0)} -> 0 | Q15: {=IF(TRIM($D15)="SET",IF($K15="Steak Set1",ROUNDDOWN(IFERROR(MIN(_xlfn._xlws.FILTER(O$3:O$650,ISNUMBER(MATCH(TRIM($B$3:$B$650),TRIM(_xlfn.TEXTSPLIT($N15,",")),0)))),0)/4,0)+P15,IF(IFERROR(MIN(_xlfn._xlws.FILTER(O$3:O$650,ISNUMBER(MATCH(TRIM($B$3:$B$650),TRIM(_xlfn.TEXTSPLIT($N15,",")),0)))),0)>=$E$1,IFERROR(MIN(_xlfn._xlws.FILTER(O$3:O$650,ISNUMBER(MATCH(TRIM($B$3:$B$650),TRIM(_xlfn.TEXTSPLIT($N15,",")),0)))),0)+P15,P15)),IF(TRIM($D15)="EA",IF(TRIM($E15)="M",ROUNDUP(O15*0.85,0),IF(TRIM($E15)="P",O15,P15)),P15))} -> #VALUE! | T15: {=IFERROR(IF(D15="SET",_xlfn.TEXTJOIN(", ",TRUE,_xlfn._xlws.FILTER(TRANSPOSE(TRIM(_xlfn.TEXTSPLIT(N15,","))),COUNTIFS(B$3:B$650,TRANSPOSE(TRIM(_xlfn.TEXTSPLIT(N15,","))),O$3:O$650,"<="&$T$1))),""),"")}
A16: 20120 | B16: 20120 | C16: FRI | D16: EA | E16: M | H16: TT 2" SPATULA-STIFF, WLNT | I16: =ISNUMBER(SEARCH($I$2,H16)) -> FALSE | J16: Trade Tools | K16: Trade Tools | L16: Trade Tools | O16: N/A | P16: {=_xlfn.XLOOKUP(TRIM(B16),TRIM('[1]wc-product-export-16-3-2026-177'!$A:$A),'[1]wc-product-export-16-3-2026-177'!$D:$D,0,0)} -> 0 | Q16: {=IF(TRIM($D16)="SET",IF($K16="Steak Set1",ROUNDDOWN(IFERROR(MIN(_xlfn._xlws.FILTER(O$3:O$650,ISNUMBER(MATCH(TRIM($B$3:$B$650),TRIM(_xlfn.TEXTSPLIT($N16,",")),0)))),0)/4,0)+P16,IF(IFERROR(MIN(_xlfn._xlws.FILTER(O$3:O$650,ISNUMBER(MATCH(TRIM($B$3:$B$650),TRIM(_xlfn.TEXTSPLIT($N16,",")),0)))),0)>=$E$1,IFERROR(MIN(_xlfn._xlws.FILTER(O$3:O$650,ISNUMBER(MATCH(TRIM($B$3:$B$650),TRIM(_xlfn.TEXTSPLIT($N16,",")),0)))),0)+P16,P16)),IF(TRIM($D16)="EA",IF(TRIM($E16)="M",ROUNDUP(O16*0.85,0),IF(TRIM($E16)="P",O16,P16)),P16))} -> #VALUE! | T16: {=IFERROR(IF(D16="SET",_xlfn.TEXTJOIN(", ",TRUE,_xlfn._xlws.FILTER(TRANSPOSE(TRIM(_xlfn.TEXTSPLIT(N16,","))),COUNTIFS(B$3:B$650,TRANSPOSE(TRIM(_xlfn.TEXTSPLIT(N16,","))),O$3:O$650,"<="&$T$1))),""),"")}
A17: 20140 | B17: 20140 | C17: FRI | D17: EA | E17: M | H17: TT 3" SPATULA-FLEX, WLNT | I17: =ISNUMBER(SEARCH($I$2,H17)) -> FALSE | J17: Trade Tools | K17: Trade Tools | L17: Trade Tools | O17: N/A | P17: {=_xlfn.XLOOKUP(TRIM(B17),TRIM('[1]wc-product-export-16-3-2026-177'!$A:$A),'[1]wc-product-export-16-3-2026-177'!$D:$D,0,0)} -> 0 | Q17: {=IF(TRIM($D17)="SET",IF($K17="Steak Set1",ROUNDDOWN(IFERROR(MIN(_xlfn._xlws.FILTER(O$3:O$650,ISNUMBER(MATCH(TRIM($B$3:$B$650),TRIM(_xlfn.TEXTSPLIT($N17,",")),0)))),0)/4,0)+P17,IF(IFERROR(MIN(_xlfn._xlws.FILTER(O$3:O$650,ISNUMBER(MATCH(TRIM($B$3:$B$650),TRIM(_xlfn.TEXTSPLIT($N17,",")),0)))),0)>=$E$1,IFERROR(MIN(_xlfn._xlws.FILTER(O$3:O$650,ISNUMBER(MATCH(TRIM($B$3:$B$650),TRIM(_xlfn.TEXTSPLIT($N17,",")),0)))),0)+P17,P17)),IF(TRIM($D17)="EA",IF(TRIM($E17)="M",ROUNDUP(O17*0.85,0),IF(TRIM($E17)="P",O17,P17)),P17))} -> #VALUE! | T17: {=IFERROR(IF(D17="SET",_xlfn.TEXTJOIN(", ",TRUE,_xlfn._xlws.FILTER(TRANSPOSE(TRIM(_xlfn.TEXTSPLIT(N17,","))),COUNTIFS(B$3:B$650,TRANSPOSE(TRIM(_xlfn.TEXTSPLIT(N17,","))),O$3:O$650,"<="&$T$1))),""),"")}
A18: 20220 | B18: 20220 | C18: FRI | D18: EA | E18: M | H18: TT 4" SPATULA-FLEX, WLNT | I18: =ISNUMBER(SEARCH($I$2,H18)) -> FALSE | J18: Trade Tools | K18: Trade Tools | L18: Trade Tools | O18: N/A | P18: {=_xlfn.XLOOKUP(TRIM(B18),TRIM('[1]wc-product-export-16-3-2026-177'!$A:$A),'[1]wc-product-export-16-3-2026-177'!$D:$D,0,0)} -> 0 | Q18: {=IF(TRIM($D18)="SET",IF($K18="Steak Set1",ROUNDDOWN(IFERROR(MIN(_xlfn._xlws.FILTER(O$3:O$650,ISNUMBER(MATCH(TRIM($B$3:$B$650),TRIM(_xlfn.TEXTSPLIT($N18,",")),0)))),0)/4,0)+P18,IF(IFERROR(MIN(_xlfn._xlws.FILTER(O$3:O$650,ISNUMBER(MATCH(TRIM($B$3:$B$650),TRIM(_xlfn.TEXTSPLIT($N18,",")),0)))),0)>=$E$1,IFERROR(MIN(_xlfn._xlws.FILTER(O$3:O$650,ISNUMBER(MATCH(TRIM($B$3:$B$650),TRIM(_xlfn.TEXTSPLIT($N18,",")),0)))),0)+P18,P18)),IF(TRIM($D18)="EA",IF(TRIM($E18)="M",ROUNDUP(O18*0.85,0),IF(TRIM($E18)="P",O18,P18)),P18))} -> #VALUE! | T18: {=IFERROR(IF(D18="SET",_xlfn.TEXTJOIN(", ",TRUE,_xlfn._xlws.FILTER(TRANSPOSE(TRIM(_xlfn.TEXTSPLIT(N18,","))),COUNTIFS(B$3:B$650,TRANSPOSE(TRIM(_xlfn.TEXTSPLIT(N18,","))),O$3:O$650,"<="&$T$1))),""),"")}
A19: 20300 | B19: 20300 | C19: FRI | D19: EA | E19: M | H19: TT 5" SPATULA-FLEX, WLNT | I19: =ISNUMBER(SEARCH($I$2,H19)) -> FALSE | J19: Trade Tools | K19: Trade Tools | L19: Trade Tools | O19: N/A | P19: {=_xlfn.XLOOKUP(TRIM(B19),TRIM('[1]wc-product-export-16-3-2026-177'!$A:$A),'[1]wc-product-export-16-3-2026-177'!$D:$D,0,0)} -> 0 | Q19: {=IF(TRIM($D19)="SET",IF($K19="Steak Set1",ROUNDDOWN(IFERROR(MIN(_xlfn._xlws.FILTER(O$3:O$650,ISNUMBER(MATCH(TRIM($B$3:$B$650),TRIM(_xlfn.TEXTSPLIT($N19,",")),0)))),0)/4,0)+P19,IF(IFERROR(MIN(_xlfn._xlws.FILTER(O$3:O$650,ISNUMBER(MATCH(TRIM($B$3:$B$650),TRIM(_xlfn.TEXTSPLIT($N19,",")),0)))),0)>=$E$1,IFERROR(MIN(_xlfn._xlws.FILTER(O$3:O$650,ISNUMBER(MATCH(TRIM($B$3:$B$650),TRIM(_xlfn.TEXTSPLIT($N19,",")),0)))),0)+P19,P19)),IF(TRIM($D19)="EA",IF(TRIM($E19)="M",ROUNDUP(O19*0.85,0),IF(TRIM($E19)="P",O19,P19)),P19))} -> #VALUE! | T19: {=IFERROR(IF(D19="SET",_xlfn.TEXTJOIN(", ",TRUE,_xlfn._xlws.FILTER(TRANSPOSE(TRIM(_xlfn.TEXTSPLIT(N19,","))),COUNTIFS(B$3:B$650,TRANSPOSE(TRIM(_xlfn.TEXTSPLIT(N19,","))),O$3:O$650,"<="&$T$1))),""),"")}
A20: 20360 | B20: 20360 | C20: FRI | D20: EA | E20: M | H20: 6" SPATULA-FLEX WLNT | I20: =ISNUMBER(SEARCH($I$2,H20)) -> FALSE | J20: Trade Tools | K20: Trade Tools | L20: Trade Tools | O20: N/A | P20: {=_xlfn.XLOOKUP(TRIM(B20),TRIM('[1]wc-product-export-16-3-2026-177'!$A:$A),'[1]wc-product-export-16-3-2026-177'!$D:$D,0,0)} -> 0 | Q20: {=IF(TRIM($D20)="SET",IF($K20="Steak Set1",ROUNDDOWN(IFERROR(MIN(_xlfn._xlws.FILTER(O$3:O$650,ISNUMBER(MATCH(TRIM($B$3:$B$650),TRIM(_xlfn.TEXTSPLIT($N20,",")),0)))),0)/4,0)+P20,IF(IFERROR(MIN(_xlfn._xlws.FILTER(O$3:O$650,ISNUMBER(MATCH(TRIM($B$3:$B$650),TRIM(_xlfn.TEXTSPLIT($N20,",")),0)))),0)>=$E$1,IFERROR(MIN(_xlfn._xlws.FILTER(O$3:O$650,ISNUMBER(MATCH(TRIM($B$3:$B$650),TRIM(_xlfn.TEXTSPLIT($N20,",")),0)))),0)+P20,P20)),IF(TRIM($D20)="EA",IF(TRIM($E20)="M",ROUNDUP(O20*0.85,0),IF(TRIM($E20)="P",O20,P20)),P20))} -> #VALUE! | T20: {=IFERROR(IF(D20="SET",_xlfn.TEXTJOIN(", ",TRUE,_xlfn._xlws.FILTER(TRANSPOSE(TRIM(_xlfn.TEXTSPLIT(N20,","))),COUNTIFS(B$3:B$650,TRANSPOSE(TRIM(_xlfn.TEXTSPLIT(N20,","))),O$3:O$650,"<="&$T$1))),""),"")}
A21: 5014 | B21: 05014 | C21: FRI | D21: EA | E21: P | H21: TreeSpirit™ Individual 9" Solid Wood Salad Bowls - Cherry | I21: =ISNUMBER(SEARCH($I$2,H21)) -> FALSE | J21: TreeSpirit™ | K21: Utensils | L21: Utensils | O21: 11 | P21: {=_xlfn.XLOOKUP(TRIM(B21),TRIM('[1]wc-product-export-16-3-2026-177'!$A:$A),'[1]wc-product-export-16-3-2026-177'!$D:$D,0,0)} -> 0 | Q21: {=IF(TRIM($D21)="SET",IF($K21="Steak Set1",ROUNDDOWN(IFERROR(MIN(_xlfn._xlws.FILTER(O$3:O$650,ISNUMBER(MATCH(TRIM($B$3:$B$650),TRIM(_xlfn.TEXTSPLIT($N21,",")),0)))),0)/4,0)+P21,IF(IFERROR(MIN(_xlfn._xlws.FILTER(O$3:O$650,ISNUMBER(MATCH(TRIM($B$3:$B$650),TRIM(_xlfn.TEXTSPLIT($N21,",")),0)))),0)>=$E$1,IFERROR(MIN(_xlfn._xlws.FILTER(O$3:O$650,ISNUMBER(MATCH(TRIM($B$3:$B$650),TRIM(_xlfn.TEXTSPLIT($N21,",")),0)))),0)+P21,P21)),IF(TRIM($D21)="EA",IF(TRIM($E21)="M",ROUNDUP(O21*0.85,0),IF(TRIM($E21)="P",O21,P21)),P21))} -> 11 | T21: {=IFERROR(IF(D21="SET",_xlfn.TEXTJOIN(", ",TRUE,_xlfn._xlws.FILTER(TRANSPOSE(TRIM(_xlfn.TEXTSPLIT(N21,","))),COUNTIFS(B$3:B$650,TRANSPOSE(TRIM(_xlfn.TEXTSPLIT(N21,","))),O$3:O$650,"<="&$T$1))),""),"")}
A22: 5021 | B22: 05021 | C22: FRI | D22: EA | E22: P | H22: TreeSpirit™ 12" Solid Wood Serving Bowls - Walnut | I22: =ISNUMBER(SEARCH($I$2,H22)) -> FALSE | J22: TreeSpirit™ | K22: Utensils | L22: Utensils | O22: 3 | P22: {=_xlfn.XLOOKUP(TRIM(B22),TRIM('[1]wc-product-export-16-3-2026-177'!$A:$A),'[1]wc-product-export-16-3-2026-177'!$D:$D,0,0)} -> 0 | Q22: {=IF(TRIM($D22)="SET",IF($K22="Steak Set1",ROUNDDOWN(IFERROR(MIN(_xlfn._xlws.FILTER(O$3:O$650,ISNUMBER(MATCH(TRIM($B$3:$B$650),TRIM(_xlfn.TEXTSPLIT($N22,",")),0)))),0)/4,0)+P22,IF(IFERROR(MIN(_xlfn._xlws.FILTER(O$3:O$650,ISNUMBER(MATCH(TRIM($B$3:$B$650),TRIM(_xlfn.TEXTSPLIT($N22,",")),0)))),0)>=$E$1,IFERROR(MIN(_xlfn._xlws.FILTER(O$3:O$650,ISNUMBER(MATCH(TRIM($B$3:$B$650),TRIM(_xlfn.TEXTSPLIT($N22,",")),0)))),0)+P22,P22)),IF(TRIM($D22)="EA",IF(TRIM($E22)="M",ROUNDUP(O22*0.85,0),IF(TRIM($E22)="P",O22,P22)),P22))} -> 3 | T22: {=IFERROR(IF(D22="SET",_xlfn.TEXTJOIN(", ",TRUE,_xlfn._xlws.FILTER(TRANSPOSE(TRIM(_xlfn.TEXTSPLIT(N22,","))),COUNTIFS(B$3:B$650,TRANSPOSE(TRIM(_xlfn.TEXTSPLIT(N22,","))),O$3:O$650,"<="&$T$1))),""),"")}
A23: 20420 | B23: 20420 | C23: FRI | D23: EA | E23: M | F23: X | H23: TT 6" SPATULA-FLEX, WHITE POLY | I23: =ISNUMBER(SEARCH($I$2,H23)) -> FALSE | J23: Trade Tools | K23: Trade Tools | L23: Trade Tools | O23: N/A | P23: {=_xlfn.XLOOKUP(TRIM(B23),TRIM('[1]wc-product-export-16-3-2026-177'!$A:$A),'[1]wc-product-export-16-3-2026-177'!$D:$D,0,0)} -> 0 | Q23: {=IF(TRIM($D23)="SET",IF($K23="Steak Set1",ROUNDDOWN(IFERROR(MIN(_xlfn._xlws.FILTER(O$3:O$650,ISNUMBER(MATCH(TRIM($B$3:$B$650),TRIM(_xlfn.TEXTSPLIT($N23,",")),0)))),0)/4,0)+P23,IF(IFERROR(MIN(_xlfn._xlws.FILTER(O$3:O$650,ISNUMBER(MATCH(TRIM($B$3:$B$650),TRIM(_xlfn.TEXTSPLIT($N23,",")),0)))),0)>=$E$1,IFERROR(MIN(_xlfn._xlws.FILTER(O$3:O$650,ISNUMBER(MATCH(TRIM($B$3:$B$650),TRIM(_xlfn.TEXTSPLIT($N23,",")),0)))),0)+P23,P23)),IF(TRIM($D23)="EA",IF(TRIM($E23)="M",ROUNDUP(O23*0.85,0),IF(TRIM($E23)="P",O23,P23)),P23))} -> #VALUE! | T23: {=IFERROR(IF(D23="SET",_xlfn.TEXTJOIN(", ",TRUE,_xlfn._xlws.FILTER(TRANSPOSE(TRIM(_xlfn.TEXTSPLIT(N23,","))),COUNTIFS(B$3:B$650,TRANSPOSE(TRIM(_xlfn.TEXTSPLIT(N23,","))),O$3:O$650,"<="&$T$1))),""),"")}
A24: 20440 | B24: 20440 | C24: FRI | D24: EA | E24: M | H24: TT 8" SPATULA-FLEX, WLNT | I24: =ISNUMBER(SEARCH($I$2,H24)) -> FALSE | J24: Trade Tools | K24: Trade Tools | L24: Trade Tools | O24: N/A | P24: {=_xlfn.XLOOKUP(TRIM(B24),TRIM('[1]wc-product-export-16-3-2026-177'!$A:$A),'[1]wc-product-export-16-3-2026-177'!$D:$D,0,0)} -> 0 | Q24: {=IF(TRIM($D24)="SET",IF($K24="Steak Set1",ROUNDDOWN(IFERROR(MIN(_xlfn._xlws.FILTER(O$3:O$650,ISNUMBER(MATCH(TRIM($B$3:$B$650),TRIM(_xlfn.TEXTSPLIT($N24,",")),0)))),0)/4,0)+P24,IF(IFERROR(MIN(_xlfn._xlws.FILTER(O$3:O$650,ISNUMBER(MATCH(TRIM($B$3:$B$650),TRIM(_xlfn.TEXTSPLIT($N24,",")),0)))),0)>=$E$1,IFERROR(MIN(_xlfn._xlws.FILTER(O$3:O$650,ISNUMBER(MATCH(TRIM($B$3:$B$650),TRIM(_xlfn.TEXTSPLIT($N24,",")),0)))),0)+P24,P24)),IF(TRIM($D24)="EA",IF(TRIM($E24)="M",ROUNDUP(O24*0.85,0),IF(TRIM($E24)="P",O24,P24)),P24))} -> #VALUE! | T24: {=IFERROR(IF(D24="SET",_xlfn.TEXTJOIN(", ",TRUE,_xlfn._xlws.FILTER(TRANSPOSE(TRIM(_xlfn.TEXTSPLIT(N24,","))),COUNTIFS(B$3:B$650,TRANSPOSE(TRIM(_xlfn.TEXTSPLIT(N24,","))),O$3:O$650,"<="&$T$1))),""),"")}
A25: 5022 | B25: 05022 | C25: FRI | D25: EA | E25: P | H25: TreeSpirit™ 12" Solid Wood Serving Bowls - Cherry | I25: =ISNUMBER(SEARCH($I$2,H25)) -> FALSE | J25: TreeSpirit™ | K25: Utensils | L25: Utensils | O25: 6 | P25: {=_xlfn.XLOOKUP(TRIM(B25),TRIM('[1]wc-product-export-16-3-2026-177'!$A:$A),'[1]wc-product-export-16-3-2026-177'!$D:$D,0,0)} -> 0 | Q25: {=IF(TRIM($D25)="SET",IF($K25="Steak Set1",ROUNDDOWN(IFERROR(MIN(_xlfn._xlws.FILTER(O$3:O$650,ISNUMBER(MATCH(TRIM($B$3:$B$650),TRIM(_xlfn.TEXTSPLIT($N25,",")),0)))),0)/4,0)+P25,IF(IFERROR(MIN(_xlfn._xlws.FILTER(O$3:O$650,ISNUMBER(MATCH(TRIM($B$3:$B$650),TRIM(_xlfn.TEXTSPLIT($N25,",")),0)))),0)>=$E$1,IFERROR(MIN(_xlfn._xlws.FILTER(O$3:O$650,ISNUMBER(MATCH(TRIM($B$3:$B$650),TRIM(_xlfn.TEXTSPLIT($N25,",")),0)))),0)+P25,P25)),IF(TRIM($D25)="EA",IF(TRIM($E25)="M",ROUNDUP(O25*0.85,0),IF(TRIM($E25)="P",O25,P25)),P25))} -> 6 | T25: {=IFERROR(IF(D25="SET",_xlfn.TEXTJOIN(", ",TRUE,_xlfn._xlws.FILTER(TRANSPOSE(TRIM(_xlfn.TEXTSPLIT(N25,","))),COUNTIFS(B$3:B$650,TRANSPOSE(TRIM(_xlfn.TEXTSPLIT(N25,","))),O$3:O$650,"<="&$T$1))),""),"")}
A26: 20520 | B26: 20520 | C26: FRI | D26: EA | E26: M | H26: TT 8" SPATULA-FLEX, WHITE POLY | I26: =ISNUMBER(SEARCH($I$2,H26)) -> FALSE | J26: Trade Tools | K26: Trade Tools | L26: Trade Tools | O26: N/A | P26: {=_xlfn.XLOOKUP(TRIM(B26),TRIM('[1]wc-product-export-16-3-2026-177'!$A:$A),'[1]wc-product-export-16-3-2026-177'!$D:$D,0,0)} -> 0 | Q26: {=IF(TRIM($D26)="SET",IF($K26="Steak Set1",ROUNDDOWN(IFERROR(MIN(_xlfn._xlws.FILTER(O$3:O$650,ISNUMBER(MATCH(TRIM($B$3:$B$650),TRIM(_xlfn.TEXTSPLIT($N26,",")),0)))),0)/4,0)+P26,IF(IFERROR(MIN(_xlfn._xlws.FILTER(O$3:O$650,ISNUMBER(MATCH(TRIM($B$3:$B$650),TRIM(_xlfn.TEXTSPLIT($N26,",")),0)))),0)>=$E$1,IFERROR(MIN(_xlfn._xlws.FILTER(O$3:O$650,ISNUMBER(MATCH(TRIM($B$3:$B$650),TRIM(_xlfn.TEXTSPLIT($N26,",")),0)))),0)+P26,P26)),IF(TRIM($D26)="EA",IF(TRIM($E26)="M",ROUNDUP(O26*0.85,0),IF(TRIM($E26)="P",O26,P26)),P26))} -> #VALUE! | T26: {=IFERROR(IF(D26="SET",_xlfn.TEXTJOIN(", ",TRUE,_xlfn._xlws.FILTER(TRANSPOSE(TRIM(_xlfn.TEXTSPLIT(N26,","))),COUNTIFS(B$3:B$650,TRANSPOSE(TRIM(_xlfn.TEXTSPLIT(N26,","))),O$3:O$650,"<="&$T$1))),""),"")}
A27: 20540 | B27: 20540 | C27: FRI | D27: EA | E27: M | F27: Z | H27: TT 10" SPATULA-FLEX, WLNT | I27: =ISNUMBER(SEARCH($I$2,H27)) -> FALSE | J27: Trade Tools | K27: Trade Tools | L27: Trade Tools | O27: N/A | P27: {=_xlfn.XLOOKUP(TRIM(B27),TRIM('[1]wc-product-export-16-3-2026-177'!$A:$A),'[1]wc-product-export-16-3-2026-177'!$D:$D,0,0)} -> 0 | Q27: {=IF(TRIM($D27)="SET",IF($K27="Steak Set1",ROUNDDOWN(IFERROR(MIN(_xlfn._xlws.FILTER(O$3:O$650,ISNUMBER(MATCH(TRIM($B$3:$B$650),TRIM(_xlfn.TEXTSPLIT($N27,",")),0)))),0)/4,0)+P27,IF(IFERROR(MIN(_xlfn._xlws.FILTER(O$3:O$650,ISNUMBER(MATCH(TRIM($B$3:$B$650),TRIM(_xlfn.TEXTSPLIT($N27,",")),0)))),0)>=$E$1,IFERROR(MIN(_xlfn._xlws.FILTER(O$3:O$650,ISNUMBER(MATCH(TRIM($B$3:$B$650),TRIM(_xlfn.TEXTSPLIT($N27,",")),0)))),0)+P27,P27)),IF(TRIM($D27)="EA",IF(TRIM($E27)="M",ROUNDUP(O27*0.85,0),IF(TRIM($E27)="P",O27,P27)),P27))} -> #VALUE! | T27: {=IFERROR(IF(D27="SET",_xlfn.TEXTJOIN(", ",TRUE,_xlfn._xlws.FILTER(TRANSPOSE(TRIM(_xlfn.TEXTSPLIT(N27,","))),COUNTIFS(B$3:B$650,TRANSPOSE(TRIM(_xlfn.TEXTSPLIT(N27,","))),O$3:O$650,"<="&$T$1))),""),"")}
A28: 20600 | B28: 20600 | C28: FRI | D28: EA | E28: M | H28: 10" SPATULA-FLEX, WHITE POLY | I28: =ISNUMBER(SEARCH($I$2,H28)) -> FALSE | J28: Trade Tools | K28: Trade Tools | L28: Trade Tools | O28: N/A | P28: {=_xlfn.XLOOKUP(TRIM(B28),TRIM('[1]wc-product-export-16-3-2026-177'!$A:$A),'[1]wc-product-export-16-3-2026-177'!$D:$D,0,0)} -> 0 | Q28: {=IF(TRIM($D28)="SET",IF($K28="Steak Set1",ROUNDDOWN(IFERROR(MIN(_xlfn._xlws.FILTER(O$3:O$650,ISNUMBER(MATCH(TRIM($B$3:$B$650),TRIM(_xlfn.TEXTSPLIT($N28,",")),0)))),0)/4,0)+P28,IF(IFERROR(MIN(_xlfn._xlws.FILTER(O$3:O$650,ISNUMBER(MATCH(TRIM($B$3:$B$650),TRIM(_xlfn.TEXTSPLIT($N28,",")),0)))),0)>=$E$1,IFERROR(MIN(_xlfn._xlws.FILTER(O$3:O$650,ISNUMBER(MATCH(TRIM($B$3:$B$650),TRIM(_xlfn.TEXTSPLIT($N28,",")),0)))),0)+P28,P28)),IF(TRIM($D28)="EA",IF(TRIM($E28)="M",ROUNDUP(O28*0.85,0),IF(TRIM($E28)="P",O28,P28)),P28))} -> #VALUE! | T28: {=IFERROR(IF(D28="SET",_xlfn.TEXTJOIN(", ",TRUE,_xlfn._xlws.FILTER(TRANSPOSE(TRIM(_xlfn.TEXTSPLIT(N28,","))),COUNTIFS(B$3:B$650,TRANSPOSE(TRIM(_xlfn.TEXTSPLIT(N28,","))),O$3:O$650,"<="&$T$1))),""),"")}
A29: 20620 | B29: 20620 | C29: FRI | D29: EA | E29: M | H29: TT 12" SPATULA-FLEX, WLNT | I29: =ISNUMBER(SEARCH($I$2,H29)) -> FALSE | J29: Trade Tools | K29: Trade Tools | L29: Trade Tools | O29: N/A | P29: {=_xlfn.XLOOKUP(TRIM(B29),TRIM('[1]wc-product-export-16-3-2026-177'!$A:$A),'[1]wc-product-export-16-3-2026-177'!$D:$D,0,0)} -> 0 | Q29: {=IF(TRIM($D29)="SET",IF($K29="Steak Set1",ROUNDDOWN(IFERROR(MIN(_xlfn._xlws.FILTER(O$3:O$650,ISNUMBER(MATCH(TRIM($B$3:$B$650),TRIM(_xlfn.TEXTSPLIT($N29,",")),0)))),0)/4,0)+P29,IF(IFERROR(MIN(_xlfn._xlws.FILTER(O$3:O$650,ISNUMBER(MATCH(TRIM($B$3:$B$650),TRIM(_xlfn.TEXTSPLIT($N29,",")),0)))),0)>=$E$1,IFERROR(MIN(_xlfn._xlws.FILTER(O$3:O$650,ISNUMBER(MATCH(TRIM($B$3:$B$650),TRIM(_xlfn.TEXTSPLIT($N29,",")),0)))),0)+P29,P29)),IF(TRIM($D29)="EA",IF(TRIM($E29)="M",ROUNDUP(O29*0.85,0),IF(TRIM($E29)="P",O29,P29)),P29))} -> #VALUE! | T29: {=IFERROR(IF(D29="SET",_xlfn.TEXTJOIN(", ",TRUE,_xlfn._xlws.FILTER(TRANSPOSE(TRIM(_xlfn.TEXTSPLIT(N29,","))),COUNTIFS(B$3:B$650,TRANSPOSE(TRIM(_xlfn.TEXTSPLIT(N29,","))),O$3:O$650,"<="&$T$1))),""),"")}
A30: 20700 | B30: 20700 | C30: FRI | D30: EA | E30: M | H30: TT 14" SPATULA-FLEX, WLNT | I30: =ISNUMBER(SEARCH($I$2,H30)) -> FALSE | J30: Trade Tools | K30: Trade Tools | L30: Trade Tools | O30: N/A | P30: {=_xlfn.XLOOKUP(TRIM(B30),TRIM('[1]wc-product-export-16-3-2026-177'!$A:$A),'[1]wc-product-export-16-3-2026-177'!$D:$D,0,0)} -> 0 | Q30: {=IF(TRIM($D30)="SET",IF($K30="Steak Set1",ROUNDDOWN(IFERROR(MIN(_xlfn._xlws.FILTER(O$3:O$650,ISNUMBER(MATCH(TRIM($B$3:$B$650),TRIM(_xlfn.TEXTSPLIT($N30,",")),0)))),0)/4,0)+P30,IF(IFERROR(MIN(_xlfn._xlws.FILTER(O$3:O$650,ISNUMBER(MATCH(TRIM($B$3:$B$650),TRIM(_xlfn.TEXTSPLIT($N30,",")),0)))),0)>=$E$1,IFERROR(MIN(_xlfn._xlws.FILTER(O$3:O$650,ISNUMBER(MATCH(TRIM($B$3:$B$650),TRIM(_xlfn.TEXTSPLIT($N30,",")),0)))),0)+P30,P30)),IF(TRIM($D30)="EA",IF(TRIM($E30)="M",ROUNDUP(O30*0.85,0),IF(TRIM($E30)="P",O30,P30)),P30))} -> #VALUE! | T30: {=IFERROR(IF(D30="SET",_xlfn.TEXTJOIN(", ",TRUE,_xlfn._xlws.FILTER(TRANSPOSE(TRIM(_xlfn.TEXTSPLIT(N30,","))),COUNTIFS(B$3:B$650,TRANSPOSE(TRIM(_xlfn.TEXTSPLIT(N30,","))),O$3:O$650,"<="&$T$1))),""),"")}
A31: 20720 | B31: 20720 | C31: FRI | D31: EA | E31: M | H31: 14" SPATULA-FLEX, WHITE POLY | I31: =ISNUMBER(SEARCH($I$2,H31)) -> FALSE | J31: Trade Tools | K31: Trade Tools | L31: Trade Tools | O31: N/A | P31: {=_xlfn.XLOOKUP(TRIM(B31),TRIM('[1]wc-product-export-16-3-2026-177'!$A:$A),'[1]wc-product-export-16-3-2026-177'!$D:$D,0,0)} -> 0 | Q31: {=IF(TRIM($D31)="SET",IF($K31="Steak Set1",ROUNDDOWN(IFERROR(MIN(_xlfn._xlws.FILTER(O$3:O$650,ISNUMBER(MATCH(TRIM($B$3:$B$650),TRIM(_xlfn.TEXTSPLIT($N31,",")),0)))),0)/4,0)+P31,IF(IFERROR(MIN(_xlfn._xlws.FILTER(O$3:O$650,ISNUMBER(MATCH(TRIM($B$3:$B$650),TRIM(_xlfn.TEXTSPLIT($N31,",")),0)))),0)>=$E$1,IFERROR(MIN(_xlfn._xlws.FILTER(O$3:O$650,ISNUMBER(MATCH(TRIM($B$3:$B$650),TRIM(_xlfn.TEXTSPLIT($N31,",")),0)))),0)+P31,P31)),IF(TRIM($D31)="EA",IF(TRIM($E31)="M",ROUNDUP(O31*0.85,0),IF(TRIM($E31)="P",O31,P31)),P31))} -> #VALUE! | T31: {=IFERROR(IF(D31="SET",_xlfn.TEXTJOIN(", ",TRUE,_xlfn._xlws.FILTER(TRANSPOSE(TRIM(_xlfn.TEXTSPLIT(N31,","))),COUNTIFS(B$3:B$650,TRANSPOSE(TRIM(_xlfn.TEXTSPLIT(N31,","))),O$3:O$650,"<="&$T$1))),""),"")}
A32: 21140 | B32: 21140 | C32: FRI | D32: EA | E32: M | H32: TT 3" PALETTE KNIFE, WLNT | I32: =ISNUMBER(SEARCH($I$2,H32)) -> FALSE | J32: Trade Tools | K32: Trade Tools | L32: Trade Tools | O32: N/A | P32: {=_xlfn.XLOOKUP(TRIM(B32),TRIM('[1]wc-product-export-16-3-2026-177'!$A:$A),'[1]wc-product-export-16-3-2026-177'!$D:$D,0,0)} -> 0 | Q32: {=IF(TRIM($D32)="SET",IF($K32="Steak Set1",ROUNDDOWN(IFERROR(MIN(_xlfn._xlws.FILTER(O$3:O$650,ISNUMBER(MATCH(TRIM($B$3:$B$650),TRIM(_xlfn.TEXTSPLIT($N32,",")),0)))),0)/4,0)+P32,IF(IFERROR(MIN(_xlfn._xlws.FILTER(O$3:O$650,ISNUMBER(MATCH(TRIM($B$3:$B$650),TRIM(_xlfn.TEXTSPLIT($N32,",")),0)))),0)>=$E$1,IFERROR(MIN(_xlfn._xlws.FILTER(O$3:O$650,ISNUMBER(MATCH(TRIM($B$3:$B$650),TRIM(_xlfn.TEXTSPLIT($N32,",")),0)))),0)+P32,P32)),IF(TRIM($D32)="EA",IF(TRIM($E32)="M",ROUNDUP(O32*0.85,0),IF(TRIM($E32)="P",O32,P32)),P32))} -> #VALUE! | T32: {=IFERROR(IF(D32="SET",_xlfn.TEXTJOIN(", ",TRUE,_xlfn._xlws.FILTER(TRANSPOSE(TRIM(_xlfn.TEXTSPLIT(N32,","))),COUNTIFS(B$3:B$650,TRANSPOSE(TRIM(_xlfn.TEXTSPLIT(N32,","))),O$3:O$650,"<="&$T$1))),""),"")}
A33: 5025 | B33: 05025 | C33: FRI | D33: EA | E33: P | H33: TreeSpirit™ 15" Solid Wood Serving Bowls - Walnut | I33: =ISNUMBER(SEARCH($I$2,H33)) -> FALSE | J33: TreeSpirit™ | K33: Utensils | L33: Utensils | O33: 0 | P33: {=_xlfn.XLOOKUP(TRIM(B33),TRIM('[1]wc-product-export-16-3-2026-177'!$A:$A),'[1]wc-product-export-16-3-2026-177'!$D:$D,0,0)} -> 0 | Q33: {=IF(TRIM($D33)="SET",IF($K33="Steak Set1",ROUNDDOWN(IFERROR(MIN(_xlfn._xlws.FILTER(O$3:O$650,ISNUMBER(MATCH(TRIM($B$3:$B$650),TRIM(_xlfn.TEXTSPLIT($N33,",")),0)))),0)/4,0)+P33,IF(IFERROR(MIN(_xlfn._xlws.FILTER(O$3:O$650,ISNUMBER(MATCH(TRIM($B$3:$B$650),TRIM(_xlfn.TEXTSPLIT($N33,",")),0)))),0)>=$E$1,IFERROR(MIN(_xlfn._xlws.FILTER(O$3:O$650,ISNUMBER(MATCH(TRIM($B$3:$B$650),TRIM(_xlfn.TEXTSPLIT($N33,",")),0)))),0)+P33,P33)),IF(TRIM($D33)="EA",IF(TRIM($E33)="M",ROUNDUP(O33*0.85,0),IF(TRIM($E33)="P",O33,P33)),P33))} -> 0 | T33: {=IFERROR(IF(D33="SET",_xlfn.TEXTJOIN(", ",TRUE,_xlfn._xlws.FILTER(TRANSPOSE(TRIM(_xlfn.TEXTSPLIT(N33,","))),COUNTIFS(B$3:B$650,TRANSPOSE(TRIM(_xlfn.TEXTSPLIT(N33,","))),O$3:O$650,"<="&$T$1))),""),"")}
A34: 21220 | B34: 21220 | C34: FRI | D34: EA | E34: M | F34: Z | H34: TT 4" PALETTE KNIFE, WLNT | I34: =ISNUMBER(SEARCH($I$2,H34)) -> FALSE | J34: Trade Tools | K34: Trade Tools | L34: Trade Tools | O34: N/A | P34: {=_xlfn.XLOOKUP(TRIM(B34),TRIM('[1]wc-product-export-16-3-2026-177'!$A:$A),'[1]wc-product-export-16-3-2026-177'!$D:$D,0,0)} -> 0 | Q34: {=IF(TRIM($D34)="SET",IF($K34="Steak Set1",ROUNDDOWN(IFERROR(MIN(_xlfn._xlws.FILTER(O$3:O$650,ISNUMBER(MATCH(TRIM($B$3:$B$650),TRIM(_xlfn.TEXTSPLIT($N34,",")),0)))),0)/4,0)+P34,IF(IFERROR(MIN(_xlfn._xlws.FILTER(O$3:O$650,ISNUMBER(MATCH(TRIM($B$3:$B$650),TRIM(_xlfn.TEXTSPLIT($N34,",")),0)))),0)>=$E$1,IFERROR(MIN(_xlfn._xlws.FILTER(O$3:O$650,ISNUMBER(MATCH(TRIM($B$3:$B$650),TRIM(_xlfn.TEXTSPLIT($N34,",")),0)))),0)+P34,P34)),IF(TRIM($D34)="EA",IF(TRIM($E34)="M",ROUNDUP(O34*0.85,0),IF(TRIM($E34)="P",O34,P34)),P34))} -> #VALUE! | T34: {=IFERROR(IF(D34="SET",_xlfn.TEXTJOIN(", ",TRUE,_xlfn._xlws.FILTER(TRANSPOSE(TRIM(_xlfn.TEXTSPLIT(N34,","))),COUNTIFS(B$3:B$650,TRANSPOSE(TRIM(_xlfn.TEXTSPLIT(N34,","))),O$3:O$650,"<="&$T$1))),""),"")}
A35: 5026 | B35: 05026 | C35: FRI | D35: EA | E35: P | H35: TreeSpirit™ 15" Solid Wood Serving Bowls - Cherry | I35: =ISNUMBER(SEARCH($I$2,H35)) -> FALSE | J35: TreeSpirit™ | K35: Utensils | L35: Utensils | O35: 1 | P35: {=_xlfn.XLOOKUP(TRIM(B35),TRIM('[1]wc-product-export-16-3-2026-177'!$A:$A),'[1]wc-product-export-16-3-2026-177'!$D:$D,0,0)} -> 0 | Q35: {=IF(TRIM($D35)="SET",IF($K35="Steak Set1",ROUNDDOWN(IFERROR(MIN(_xlfn._xlws.FILTER(O$3:O$650,ISNUMBER(MATCH(TRIM($B$3:$B$650),TRIM(_xlfn.TEXTSPLIT($N35,",")),0)))),0)/4,0)+P35,IF(IFERROR(MIN(_xlfn._xlws.FILTER(O$3:O$650,ISNUMBER(MATCH(TRIM($B$3:$B$650),TRIM(_xlfn.TEXTSPLIT($N35,",")),0)))),0)>=$E$1,IFERROR(MIN(_xlfn._xlws.FILTER(O$3:O$650,ISNUMBER(MATCH(TRIM($B$3:$B$650),TRIM(_xlfn.TEXTSPLIT($N35,",")),0)))),0)+P35,P35)),IF(TRIM($D35)="EA",IF(TRIM($E35)="M",ROUNDUP(O35*0.85,0),IF(TRIM($E35)="P",O35,P35)),P35))} -> 1 | T35: {=IFERROR(IF(D35="SET",_xlfn.TEXTJOIN(", ",TRUE,_xlfn._xlws.FILTER(TRANSPOSE(TRIM(_xlfn.TEXTSPLIT(N35,","))),COUNTIFS(B$3:B$650,TRANSPOSE(TRIM(_xlfn.TEXTSPLIT(N35,","))),O$3:O$650,"<="&$T$1))),""),"")}
A36: 5004 | B36: 05004 | C36: FRI | D36: EA | E36: P | F36: X | H36: TreeSpirit™ Individual 7.5" Solid Wood Salad Bowls - Maple | I36: =ISNUMBER(SEARCH($I$2,H36)) -> FALSE | J36: TreeSpirit™ | K36: Utensils | L36: Utensils | O36: N/A | P36: {=_xlfn.XLOOKUP(TRIM(B36),TRIM('[1]wc-product-export-16-3-2026-177'!$A:$A),'[1]wc-product-export-16-3-2026-177'!$D:$D,0,0)} -> 0 | Q36: {=IF(TRIM($D36)="SET",IF($K36="Steak Set1",ROUNDDOWN(IFERROR(MIN(_xlfn._xlws.FILTER(O$3:O$650,ISNUMBER(MATCH(TRIM($B$3:$B$650),TRIM(_xlfn.TEXTSPLIT($N36,",")),0)))),0)/4,0)+P36,IF(IFERROR(MIN(_xlfn._xlws.FILTER(O$3:O$650,ISNUMBER(MATCH(TRIM($B$3:$B$650),TRIM(_xlfn.TEXTSPLIT($N36,",")),0)))),0)>=$E$1,IFERROR(MIN(_xlfn._xlws.FILTER(O$3:O$650,ISNUMBER(MATCH(TRIM($B$3:$B$650),TRIM(_xlfn.TEXTSPLIT($N36,",")),0)))),0)+P36,P36)),IF(TRIM($D36)="EA",IF(TRIM($E36)="M",ROUNDUP(O36*0.85,0),IF(TRIM($E36)="P",O36,P36)),P36))} -> N/A | T36: {=IFERROR(IF(D36="SET",_xlfn.TEXTJOIN(", ",TRUE,_xlfn._xlws.FILTER(TRANSPOSE(TRIM(_xlfn.TEXTSPLIT(N36,","))),COUNTIFS(B$3:B$650,TRANSPOSE(TRIM(_xlfn.TEXTSPLIT(N36,","))),O$3:O$650,"<="&$T$1))),""),"")}
A37: 5028 | B37: 05028 | C37: FRI | D37: SET | E37: P | H37: TreeSpirit™ 7-Piece Salad Bowl and Serving Sets (Walnut - Medium) | I37: =ISNUMBER(SEARCH($I$2,H37)) -> FALSE | J37: TreeSpirit™ | K37: Utensils | L37: Utensils | N37: 05021,05005,05045 | O37: 4 | P37: {=_xlfn.XLOOKUP(TRIM(B37),TRIM('[1]wc-product-export-16-3-2026-177'!$A:$A),'[1]wc-product-export-16-3-2026-177'!$D:$D,0,0)} -> 1 | Q37: {=IF(TRIM($D37)="SET",IF($K37="Steak Set1",ROUNDDOWN(IFERROR(MIN(_xlfn._xlws.FILTER(O$3:O$650,ISNUMBER(MATCH(TRIM($B$3:$B$650),TRIM(_xlfn.TEXTSPLIT($N37,",")),0)))),0)/4,0)+P37,IF(IFERROR(MIN(_xlfn._xlws.FILTER(O$3:O$650,ISNUMBER(MATCH(TRIM($B$3:$B$650),TRIM(_xlfn.TEXTSPLIT($N37,",")),0)))),0)>=$E$1,IFERROR(MIN(_xlfn._xlws.FILTER(O$3:O$650,ISNUMBER(MATCH(TRIM($B$3:$B$650),TRIM(_xlfn.TEXTSPLIT($N37,",")),0)))),0)+P37,P37)),IF(TRIM($D37)="EA",IF(TRIM($E37)="M",ROUNDUP(O37*0.85,0),IF(TRIM($E37)="P",O37,P37)),P37))} -> 4 | T37: {=IFERROR(IF(D37="SET",_xlfn.TEXTJOIN(", ",TRUE,_xlfn._xlws.FILTER(TRANSPOSE(TRIM(_xlfn.TEXTSPLIT(N37,","))),COUNTIFS(B$3:B$650,TRANSPOSE(TRIM(_xlfn.TEXTSPLIT(N37,","))),O$3:O$650,"<="&$T$1))),""),"")} -> 05021
A38: 5029 | B38: 05029 | C38: FRI | D38: SET | E38: P | H38: TreeSpirit™ 7-Piece Salad Bowl and Serving Sets (Cherry - Medium) | I38: =ISNUMBER(SEARCH($I$2,H38)) -> FALSE | J38: TreeSpirit™ | K38: Utensils | L38: Utensils | N38: 05022,05006,05046 | O38: 2 | P38: {=_xlfn.XLOOKUP(TRIM(B38),TRIM('[1]wc-product-export-16-3-2026-177'!$A:$A),'[1]wc-product-export-16-3-2026-177'!$D:$D,0,0)} -> 0 | Q38: {=IF(TRIM($D38)="SET",IF($K38="Steak Set1",ROUNDDOWN(IFERROR(MIN(_xlfn._xlws.FILTER(O$3:O$650,ISNUMBER(MATCH(TRIM($B$3:$B$650),TRIM(_xlfn.TEXTSPLIT($N38,",")),0)))),0)/4,0)+P38,IF(IFERROR(MIN(_xlfn._xlws.FILTER(O$3:O$650,ISNUMBER(MATCH(TRIM($B$3:$B$650),TRIM(_xlfn.TEXTSPLIT($N38,",")),0)))),0)>=$E$1,IFERROR(MIN(_xlfn._xlws.FILTER(O$3:O$650,ISNUMBER(MATCH(TRIM($B$3:$B$650),TRIM(_xlfn.TEXTSPLIT($N38,",")),0)))),0)+P38,P38)),IF(TRIM($D38)="EA",IF(TRIM($E38)="M",ROUNDUP(O38*0.85,0),IF(TRIM($E38)="P",O38,P38)),P38))} -> 2 | T38: {=IFERROR(IF(D38="SET",_xlfn.TEXTJOIN(", ",TRUE,_xlfn._xlws.FILTER(TRANSPOSE(TRIM(_xlfn.TEXTSPLIT(N38,","))),COUNTIFS(B$3:B$650,TRANSPOSE(TRIM(_xlfn.TEXTSPLIT(N38,","))),O$3:O$650,"<="&$T$1))),""),"")} -> 05046
A39: 5012 | B39: 05012 | C39: FRI | D39: EA | E39: P | F39: X | H39: TreeSpirit™ Individual 9" Solid Wood Salad Bowls - Maple | I39: =ISNUMBER(SEARCH($I$2,H39)) -> FALSE | J39: TreeSpirit™ | K39: Utensils | L39: Utensils | O39: N/A | P39: {=_xlfn.XLOOKUP(TRIM(B39),TRIM('[1]wc-product-export-16-3-2026-177'!$A:$A),'[1]wc-product-export-16-3-2026-177'!$D:$D,0,0)} -> 0 | Q39: {=IF(TRIM($D39)="SET",IF($K39="Steak Set1",ROUNDDOWN(IFERROR(MIN(_xlfn._xlws.FILTER(O$3:O$650,ISNUMBER(MATCH(TRIM($B$3:$B$650),TRIM(_xlfn.TEXTSPLIT($N39,",")),0)))),0)/4,0)+P39,IF(IFERROR(MIN(_xlfn._xlws.FILTER(O$3:O$650,ISNUMBER(MATCH(TRIM($B$3:$B$650),TRIM(_xlfn.TEXTSPLIT($N39,",")),0)))),0)>=$E$1,IFERROR(MIN(_xlfn._xlws.FILTER(O$3:O$650,ISNUMBER(MATCH(TRIM($B$3:$B$650),TRIM(_xlfn.TEXTSPLIT($N39,",")),0)))),0)+P39,P39)),IF(TRIM($D39)="EA",IF(TRIM($E39)="M",ROUNDUP(O39*0.85,0),IF(TRIM($E39)="P",O39,P39)),P39))} -> N/A | T39: {=IFERROR(IF(D39="SET",_xlfn.TEXTJOIN(", ",TRUE,_xlfn._xlws.FILTER(TRANSPOSE(TRIM(_xlfn.TEXTSPLIT(N39,","))),COUNTIFS(B$3:B$650,TRANSPOSE(TRIM(_xlfn.TEXTSPLIT(N39,","))),O$3:O$650,"<="&$T$1))),""),"")}
A40: 5031 | B40: 05031 | C40: FRI | D40: SET | E40: P | H40: TreeSpirit™ 7-Piece Salad Bowl and Serving Sets (Walnut - Large) | I40: =ISNUMBER(SEARCH($I$2,H40)) -> FALSE | J40: TreeSpirit™ | K40: Utensils | L40: Utensils | N40: 05025,05013,05048 | O40: 0 | P40: {=_xlfn.XLOOKUP(TRIM(B40),TRIM('[1]wc-product-export-16-3-2026-177'!$A:$A),'[1]wc-product-export-16-3-2026-177'!$D:$D,0,0)} -> 0 | Q40: {=IF(TRIM($D40)="SET",IF($K40="Steak Set1",ROUNDDOWN(IFERROR(MIN(_xlfn._xlws.FILTER(O$3:O$650,ISNUMBER(MATCH(TRIM($B$3:$B$650),TRIM(_xlfn.TEXTSPLIT($N40,",")),0)))),0)/4,0)+P40,IF(IFERROR(MIN(_xlfn._xlws.FILTER(O$3:O$650,ISNUMBER(MATCH(TRIM($B$3:$B$650),TRIM(_xlfn.TEXTSPLIT($N40,",")),0)))),0)>=$E$1,IFERROR(MIN(_xlfn._xlws.FILTER(O$3:O$650,ISNUMBER(MATCH(TRIM($B$3:$B$650),TRIM(_xlfn.TEXTSPLIT($N40,",")),0)))),0)+P40,P40)),IF(TRIM($D40)="EA",IF(TRIM($E40)="M",ROUNDUP(O40*0.85,0),IF(TRIM($E40)="P",O40,P40)),P40))} -> 0 | T40: {=IFERROR(IF(D40="SET",_xlfn.TEXTJOIN(", ",TRUE,_xlfn._xlws.FILTER(TRANSPOSE(TRIM(_xlfn.TEXTSPLIT(N40,","))),COUNTIFS(B$3:B$650,TRANSPOSE(TRIM(_xlfn.TEXTSPLIT(N40,","))),O$3:O$650,"<="&$T$1))),""),"")} -> 05025, 05048
...

Sheet SILICONES
A1: DATE: 11/14/2025
A3: SKU | B3: DESCRIPTION | C3: BACKSTOCK | D3: IN TRAY | E3: TOTAL
A4: 07004 | B4: Original HotSpot™ (7" x 7") - Green | C4: 840 | D4: 100 | E4: 940 | I4: 10110 | J4: 2573
A5: 07006 | B5: Original HotSpot™ (7" x 7") - Black | C5: 3120 | D5: 80 | E5: 3200 | I5: 10111 | J5: 106
A6: 07008 | B6: Original HotSpot™ (7" x 7") - Blue | C6: 960 | D6: 45 | E6: 1005 | I6: 10112 | J6: 4287
A7: 07012 | B7: Original HotSpot™ (7" x 7") - White | C7: 820 | D7: 130 | E7: 950 | I7: 10113 | J7: 5144
A8: 07024 | B8: HotSpot™ 4″ x 4″ Red Silicone Coasters, 4-Piece Set - Red | C8: 1540 | D8: 40 | E8: 1580
A9: 07074 | B9: Original HotSpot™ Round (8" Diameter) - Black | C9: 2000 | D9: 70 | E9: 2070
A10: 07086 | B10: Big HotSpot™ (11.5" x 11.5") - Black | C10: 1800 | D10: 30 | E10: 1830
A11: 07088 | B11: Big HotSpot™ (11.5" x 11.5") - Blue | C11: 60 | D11: 50 | E11: 110
A12: 07090 | B12: Big HotSpot™ (11.5" x 11.5") - Red | C12: 1620 | D12: 12 | E12: 1632
A13: 07091 | B13: Big HotSpot™ (11.5" x 11.5") - Clear | C13: 1000 | D13: 10 | E13: 1010
A14: 07242 | B14: Original HotSpot™ (7" x 7") - Mango | C14: 360 | D14: 70 | E14: 430
A15: 07300 | B15: HotSpot™ HotHandle™ Large (6" x 1.5") - Red | C15: 1080 | D15: 60 | E15: 1140
A16: 07304 | B16: HotSpot™ HotHandle™ Large (6" x 1.5") - Black | C16: 960 | D16: 150 | E16: 1110
A17: 07308 | B17: HotSpot™ HotHandle™ Small (5" x 1") - Red | C17: 1440 | D17: 66 | E17: 1506
A18: 07309 | B18: HotSpot™ HotHandle™ Small (5" x 1") - Black | C18: 1560 | D18: 120 | E18: 1680
A19: 07394 | B19: Original HotSpot™ (7" x 7") - Goldenrod | C19: 240 | D19: 60 | E19: 300
... A39: 07511 | B39: HotSpot™ Collapsible Funnel (4.75" Diameter) - Yellow | C39: 360 | D39: 95 | E39: 455
A41: 10110 | B41: 2573
A42: 10111 | B42: 106
A43: 10112 | B43: 4287
A44: 10113 | B44: 5144

Sheet IN STOCK%
A1: IN STOCK % REPORT
A2: CATEGORY | B2: EA/SET | C2: # Items | D2: 46090 | E2: 46091 | F2: 46092 | G2: 46093 | H2: 46094
A3: Forged FIRE | B3: EA | C3: =COUNTIFS(INVENTORY!D:D,B3,INVENTORY!J:J,'IN STOCK%'!A3) -> 24 | D3: =IFERROR(IF(COUNTIFS(INVENTORY!$J:$J,$A3,INVENTORY!$D:$D,$B3, INVENTORY!Q:Q,">0")/$C3=1,"",COUNTIFS(INVENTORY!$J:$J,$A3,INVENTORY!$D:$D,$B3,INVENTORY!Q:Q,">0")/$C3),"N/A") -> 0.83333333 | E3: =IFERROR(IF(COUNTIFS(INVENTORY!$J:$J,$A3,INVENTORY!$D:$D,$B3, INVENTORY!#REF!,">0")/$C3=1,"",COUNTIFS(INVENTORY!$J:$J,$A3,INVENTORY!$D:$D,$B3,INVENTORY!#REF!,">0")/$C3),"N/A") -> N/A | F3: =IFERROR(IF(COUNTIFS(INVENTORY!$J:$J,$A3,INVENTORY!$D:$D,$B3, INVENTORY!#REF!,">0")/$C3=1,"",COUNTIFS(INVENTORY!$J:$J,$A3,INVENTORY!$D:$D,$B3,INVENTORY!#REF!,">0")/$C3),"N/A") -> N/A | G3: =IFERROR(IF(COUNTIFS(INVENTORY!$J:$J,$A3,INVENTORY!$D:$D,$B3, INVENTORY!#REF!,">0")/$C3=1,"",COUNTIFS(INVENTORY!$J:$J,$A3,INVENTORY!$D:$D,$B3,INVENTORY!#REF!,">0")/$C3),"N/A") -> N/A | H3: =IFERROR(IF(COUNTIFS(INVENTORY!$J:$J,$A3,INVENTORY!$D:$D,$B3, INVENTORY!#REF!,">0")/$C3=1,"",COUNTIFS(INVENTORY!$J:$J,$A3,INVENTORY!$D:$D,$B3,INVENTORY!#REF!,">0")/$C3),"N/A") -> N/A
A4: Forged ICE | B4: EA | C4: =COUNTIFS(INVENTORY!D:D,B4,INVENTORY!J:J,'IN STOCK%'!A4) -> 24 | D4: =IFERROR(IF(COUNTIFS(INVENTORY!$J:$J,$A4,INVENTORY!$D:$D,$B4, INVENTORY!Q:Q,">0")/$C4=1,"",COUNTIFS(INVENTORY!$J:$J,$A4,INVENTORY!$D:$D,$B4,INVENTORY!Q:Q,">0")/$C4),"N/A") -> 0.58333333 | E4: =IFERROR(IF(COUNTIFS(INVENTORY!$J:$J,$A4,INVENTORY!$D:$D,$B4, INVENTORY!#REF!,">0")/$C4=1,"",COUNTIFS(INVENTORY!$J:$J,$A4,INVENTORY!$D:$D,$B4,INVENTORY!#REF!,">0")/$C4),"N/A") -> N/A | F4: =IFERROR(IF(COUNTIFS(INVENTORY!$J:$J,$A4,INVENTORY!$D:$D,$B4, INVENTORY!#REF!,">0")/$C4=1,"",COUNTIFS(INVENTORY!$J:$J,$A4,INVENTORY!$D:$D,$B4,INVENTORY!#REF!,">0")/$C4),"N/A") -> N/A | G4: =IFERROR(IF(COUNTIFS(INVENTORY!$J:$J,$A4,INVENTORY!$D:$D,$B4, INVENTORY!#REF!,">0")/$C4=1,"",COUNTIFS(INVENTORY!$J:$J,$A4,INVENTORY!$D:$D,$B4,INVENTORY!#REF!,">0")/$C4),"N/A") -> N/A | H4: =IFERROR(IF(COUNTIFS(INVENTORY!$J:$J,$A4,INVENTORY!$D:$D,$B4, INVENTORY!#REF!,">0")/$C4=1,"",COUNTIFS(INVENTORY!$J:$J,$A4,INVENTORY!$D:$D,$B4,INVENTORY!#REF!,">0")/$C4),"N/A") -> N/A
A5: Forged SIERRA | B5: EA | C5: =COUNTIFS(INVENTORY!D:D,B5,INVENTORY!J:J,'IN STOCK%'!A5) -> 24 | D5: =IFERROR(IF(COUNTIFS(INVENTORY!$J:$J,$A5,INVENTORY!$D:$D,$B5, INVENTORY!Q:Q,">0")/$C5=1,"",COUNTIFS(INVENTORY!$J:$J,$A5,INVENTORY!$D:$D,$B5,INVENTORY!Q:Q,">0")/$C5),"N/A") -> 0.75 | E5: =IFERROR(IF(COUNTIFS(INVENTORY!$J:$J,$A5,INVENTORY!$D:$D,$B5, INVENTORY!#REF!,">0")/$C5=1,"",COUNTIFS(INVENTORY!$J:$J,$A5,INVENTORY!$D:$D,$B5,INVENTORY!#REF!,">0")/$C5),"N/A") -> N/A | F5: =IFERROR(IF(COUNTIFS(INVENTORY!$J:$J,$A5,INVENTORY!$D:$D,$B5, INVENTORY!#REF!,">0")/$C5=1,"",COUNTIFS(INVENTORY!$J:$J,$A5,INVENTORY!$D:$D,$B5,INVENTORY!#REF!,">0")/$C5),"N/A") -> N/A | G5: =IFERROR(IF(COUNTIFS(INVENTORY!$J:$J,$A5,INVENTORY!$D:$D,$B5, INVENTORY!#REF!,">0")/$C5=1,"",COUNTIFS(INVENTORY!$J:$J,$A5,INVENTORY!$D:$D,$B5,INVENTORY!#REF!,">0")/$C5),"N/A") -> N/A | H5: =IFERROR(IF(COUNTIFS(INVENTORY!$J:$J,$A5,INVENTORY!$D:$D,$B5, INVENTORY!#REF!,">0")/$C5=1,"",COUNTIFS(INVENTORY!$J:$J,$A5,INVENTORY!$D:$D,$B5,INVENTORY!#REF!,">0")/$C5),"N/A") -> N/A
A6: Forged MIDNIGHT | B6: EA | C6: =COUNTIFS(INVENTORY!D:D,B6,INVENTORY!J:J,'IN STOCK%'!A6) -> 24 | D6: =IFERROR(IF(COUNTIFS(INVENTORY!$J:$J,$A6,INVENTORY!$D:$D,$B6, INVENTORY!Q:Q,">0")/$C6=1,"",COUNTIFS(INVENTORY!$J:$J,$A6,INVENTORY!$D:$D,$B6,INVENTORY!Q:Q,">0")/$C6),"N/A") -> 0.91666667 | E6: =IFERROR(IF(COUNTIFS(INVENTORY!$J:$J,$A6,INVENTORY!$D:$D,$B6, INVENTORY!#REF!,">0")/$C6=1,"",COUNTIFS(INVENTORY!$J:$J,$A6,INVENTORY!$D:$D,$B6,INVENTORY!#REF!,">0")/$C6),"N/A") -> N/A | F6: =IFERROR(IF(COUNTIFS(INVENTORY!$J:$J,$A6,INVENTORY!$D:$D,$B6, INVENTORY!#REF!,">0")/$C6=1,"",COUNTIFS(INVENTORY!$J:$J,$A6,INVENTORY!$D:$D,$B6,INVENTORY!#REF!,">0")/$C6),"N/A") -> N/A | G6: =IFERROR(IF(COUNTIFS(INVENTORY!$J:$J,$A6,INVENTORY!$D:$D,$B6, INVENTORY!#REF!,">0")/$C6=1,"",COUNTIFS(INVENTORY!$J:$J,$A6,INVENTORY!$D:$D,$B6,INVENTORY!#REF!,">0")/$C6),"N/A") -> N/A | H6: =IFERROR(IF(COUNTIFS(INVENTORY!$J:$J,$A6,INVENTORY!$D:$D,$B6, INVENTORY!#REF!,">0")/$C6=1,"",COUNTIFS(INVENTORY!$J:$J,$A6,INVENTORY!$D:$D,$B6,INVENTORY!#REF!,">0")/$C6),"N/A") -> N/A
A7: Forged WALNUT | B7: EA | C7: =COUNTIFS(INVENTORY!D:D,B7,INVENTORY!J:J,'IN STOCK%'!A7) -> 24 | D7: =IFERROR(IF(COUNTIFS(INVENTORY!$J:$J,$A7,INVENTORY!$D:$D,$B7, INVENTORY!Q:Q,">0")/$C7=1,"",COUNTIFS(INVENTORY!$J:$J,$A7,INVENTORY!$D:$D,$B7,INVENTORY!Q:Q,">0")/$C7),"N/A") -> 0.79166667 | E7: =IFERROR(IF(COUNTIFS(INVENTORY!$J:$J,$A7,INVENTORY!$D:$D,$B7, INVENTORY!#REF!,">0")/$C7=1,"",COUNTIFS(INVENTORY!$J:$J,$A7,INVENTORY!$D:$D,$B7,INVENTORY!#REF!,">0")/$C7),"N/A") -> N/A | F7: =IFERROR(IF(COUNTIFS(INVENTORY!$J:$J,$A7,INVENTORY!$D:$D,$B7, INVENTORY!#REF!,">0")/$C7=1,"",COUNTIFS(INVENTORY!$J:$J,$A7,INVENTORY!$D:$D,$B7,INVENTORY!#REF!,">0")/$C7),"N/A") -> N/A | G7: =IFERROR(IF(COUNTIFS(INVENTORY!$J:$J,$A7,INVENTORY!$D:$D,$B7, INVENTORY!#REF!,">0")/$C7=1,"",COUNTIFS(INVENTORY!$J:$J,$A7,INVENTORY!$D:$D,$B7,INVENTORY!#REF!,">0")/$C7),"N/A") -> N/A | H7: =IFERROR(IF(COUNTIFS(INVENTORY!$J:$J,$A7,INVENTORY!$D:$D,$B7, INVENTORY!#REF!,">0")/$C7=1,"",COUNTIFS(INVENTORY!$J:$J,$A7,INVENTORY!$D:$D,$B7,INVENTORY!#REF!,">0")/$C7),"N/A") -> N/A
A8: BBQ Premier | B8: EA | C8: =COUNTIFS(INVENTORY!D:D,B8,INVENTORY!J:J,'IN STOCK%'!A8) -> 6 | D8: =IFERROR(IF(COUNTIFS(INVENTORY!$J:$J,$A8,INVENTORY!$D:$D,$B8, INVENTORY!Q:Q,">0")/$C8=1,"",COUNTIFS(INVENTORY!$J:$J,$A8,INVENTORY!$D:$D,$B8,INVENTORY!Q:Q,">0")/$C8),"N/A") | E8: =IFERROR(IF(COUNTIFS(INVENTORY!$J:$J,$A8,INVENTORY!$D:$D,$B8, INVENTORY!#REF!,">0")/$C8=1,"",COUNTIFS(INVENTORY!$J:$J,$A8,INVENTORY!$D:$D,$B8,INVENTORY!#REF!,">0")/$C8),"N/A") -> N/A | F8: =IFERROR(IF(COUNTIFS(INVENTORY!$J:$J,$A8,INVENTORY!$D:$D,$B8, INVENTORY!#REF!,">0")/$C8=1,"",COUNTIFS(INVENTORY!$J:$J,$A8,INVENTORY!$D:$D,$B8,INVENTORY!#REF!,">0")/$C8),"N/A") -> N/A | G8: =IFERROR(IF(COUNTIFS(INVENTORY!$J:$J,$A8,INVENTORY!$D:$D,$B8, INVENTORY!#REF!,">0")/$C8=1,"",COUNTIFS(INVENTORY!$J:$J,$A8,INVENTORY!$D:$D,$B8,INVENTORY!#REF!,">0")/$C8),"N/A") -> N/A | H8: =IFERROR(IF(COUNTIFS(INVENTORY!$J:$J,$A8,INVENTORY!$D:$D,$B8, INVENTORY!#REF!,">0")/$C8=1,"",COUNTIFS(INVENTORY!$J:$J,$A8,INVENTORY!$D:$D,$B8,INVENTORY!#REF!,">0")/$C8),"N/A") -> N/A
A9: BBQ Tail-gater™ | B9: EA | C9: =COUNTIFS(INVENTORY!D:D,B9,INVENTORY!J:J,'IN STOCK%'!A9) -> 5 | D9: =IFERROR(IF(COUNTIFS(INVENTORY!$J:$J,$A9,INVENTORY!$D:$D,$B9, INVENTORY!Q:Q,">0")/$C9=1,"",COUNTIFS(INVENTORY!$J:$J,$A9,INVENTORY!$D:$D,$B9,INVENTORY!Q:Q,">0")/$C9),"N/A") | E9: =IFERROR(IF(COUNTIFS(INVENTORY!$J:$J,$A9,INVENTORY!$D:$D,$B9, INVENTORY!#REF!,">0")/$C9=1,"",COUNTIFS(INVENTORY!$J:$J,$A9,INVENTORY!$D:$D,$B9,INVENTORY!#REF!,">0")/$C9),"N/A") -> N/A | F9: =IFERROR(IF(COUNTIFS(INVENTORY!$J:$J,$A9,INVENTORY!$D:$D,$B9, INVENTORY!#REF!,">0")/$C9=1,"",COUNTIFS(INVENTORY!$J:$J,$A9,INVENTORY!$D:$D,$B9,INVENTORY!#REF!,">0")/$C9),"N/A") -> N/A | G9: =IFERROR(IF(COUNTIFS(INVENTORY!$J:$J,$A9,INVENTORY!$D:$D,$B9, INVENTORY!#REF!,">0")/$C9=1,"",COUNTIFS(INVENTORY!$J:$J,$A9,INVENTORY!$D:$D,$B9,INVENTORY!#REF!,">0")/$C9),"N/A") -> N/A | H9: =IFERROR(IF(COUNTIFS(INVENTORY!$J:$J,$A9,INVENTORY!$D:$D,$B9, INVENTORY!#REF!,">0")/$C9=1,"",COUNTIFS(INVENTORY!$J:$J,$A9,INVENTORY!$D:$D,$B9,INVENTORY!#REF!,">0")/$C9),"N/A") -> N/A
A10: Brad Leone | B10: EA | C10: 5 | D10: =IFERROR(IF(COUNTIFS(INVENTORY!$J:$J,$A10,INVENTORY!$D:$D,$B10, INVENTORY!Q:Q,">0")/$C10=1,"",COUNTIFS(INVENTORY!$J:$J,$A10,INVENTORY!$D:$D,$B10,INVENTORY!Q:Q,">0")/$C10),"N/A") -> 0.6 | E10: =IFERROR(IF(COUNTIFS(INVENTORY!$J:$J,$A10,INVENTORY!$D:$D,$B10, INVENTORY!#REF!,">0")/$C10=1,"",COUNTIFS(INVENTORY!$J:$J,$A10,INVENTORY!$D:$D,$B10,INVENTORY!#REF!,">0")/$C10),"N/A") -> N/A | F10: =IFERROR(IF(COUNTIFS(INVENTORY!$J:$J,$A10,INVENTORY!$D:$D,$B10, INVENTORY!#REF!,">0")/$C10=1,"",COUNTIFS(INVENTORY!$J:$J,$A10,INVENTORY!$D:$D,$B10,INVENTORY!#REF!,">0")/$C10),"N/A") -> N/A | G10: =IFERROR(IF(COUNTIFS(INVENTORY!$J:$J,$A10,INVENTORY!$D:$D,$B10, INVENTORY!#REF!,">0")/$C10=1,"",COUNTIFS(INVENTORY!$J:$J,$A10,INVENTORY!$D:$D,$B10,INVENTORY!#REF!,">0")/$C10),"N/A") -> N/A | H10: =IFERROR(IF(COUNTIFS(INVENTORY!$J:$J,$A10,INVENTORY!$D:$D,$B10, INVENTORY!#REF!,">0")/$C10=1,"",COUNTIFS(INVENTORY!$J:$J,$A10,INVENTORY!$D:$D,$B10,INVENTORY!#REF!,">0")/$C10),"N/A") -> N/A
A11: Vintage Walnut | B11: EA | C11: =COUNTIFS(INVENTORY!D:D,B11,INVENTORY!J:J,'IN STOCK%'!A11) -> 20 | D11: =IFERROR(IF(COUNTIFS(INVENTORY!$J:$J,$A11,INVENTORY!$D:$D,$B11, INVENTORY!Q:Q,">0")/$C11=1,"",COUNTIFS(INVENTORY!$J:$J,$A11,INVENTORY!$D:$D,$B11,INVENTORY!Q:Q,">0")/$C11),"N/A") -> 0.75 | E11: =IFERROR(IF(COUNTIFS(INVENTORY!$J:$J,$A11,INVENTORY!$D:$D,$B11, INVENTORY!#REF!,">0")/$C11=1,"",COUNTIFS(INVENTORY!$J:$J,$A11,INVENTORY!$D:$D,$B11,INVENTORY!#REF!,">0")/$C11),"N/A") -> N/A | F11: =IFERROR(IF(COUNTIFS(INVENTORY!$J:$J,$A11,INVENTORY!$D:$D,$B11, INVENTORY!#REF!,">0")/$C11=1,"",COUNTIFS(INVENTORY!$J:$J,$A11,INVENTORY!$D:$D,$B11,INVENTORY!#REF!,">0")/$C11),"N/A") -> N/A | G11: =IFERROR(IF(COUNTIFS(INVENTORY!$J:$J,$A11,INVENTORY!$D:$D,$B11, INVENTORY!#REF!,">0")/$C11=1,"",COUNTIFS(INVENTORY!$J:$J,$A11,INVENTORY!$D:$D,$B11,INVENTORY!#REF!,">0")/$C11),"N/A") -> N/A | H11: =IFERROR(IF(COUNTIFS(INVENTORY!$J:$J,$A11,INVENTORY!$D:$D,$B11, INVENTORY!#REF!,">0")/$C11=1,"",COUNTIFS(INVENTORY!$J:$J,$A11,INVENTORY!$D:$D,$B11,INVENTORY!#REF!,">0")/$C11),"N/A") -> N/A
A12: Walnut Kitchen Tools | B12: EA | C12: 29 | D12: =IFERROR(IF(COUNTIFS(INVENTORY!$J:$J,$A12,INVENTORY!$D:$D,$B12, INVENTORY!Q:Q,">0")/$C12=1,"",COUNTIFS(INVENTORY!$J:$J,$A12,INVENTORY!$D:$D,$B12,INVENTORY!Q:Q,">0")/$C12),"N/A") -> 0.89655172 | E12: =IFERROR(IF(COUNTIFS(INVENTORY!$J:$J,$A12,INVENTORY!$D:$D,$B12, INVENTORY!#REF!,">0")/$C12=1,"",COUNTIFS(INVENTORY!$J:$J,$A12,INVENTORY!$D:$D,$B12,INVENTORY!#REF!,">0")/$C12),"N/A") -> N/A | F12: =IFERROR(IF(COUNTIFS(INVENTORY!$J:$J,$A12,INVENTORY!$D:$D,$B12, INVENTORY!#REF!,">0")/$C12=1,"",COUNTIFS(INVENTORY!$J:$J,$A12,INVENTORY!$D:$D,$B12,INVENTORY!#REF!,">0")/$C12),"N/A") -> N/A | G12: =IFERROR(IF(COUNTIFS(INVENTORY!$J:$J,$A12,INVENTORY!$D:$D,$B12, INVENTORY!#REF!,">0")/$C12=1,"",COUNTIFS(INVENTORY!$J:$J,$A12,INVENTORY!$D:$D,$B12,INVENTORY!#REF!,">0")/$C12),"N/A") -> N/A | H12: =IFERROR(IF(COUNTIFS(INVENTORY!$J:$J,$A12,INVENTORY!$D:$D,$B12, INVENTORY!#REF!,">0")/$C12=1,"",COUNTIFS(INVENTORY!$J:$J,$A12,INVENTORY!$D:$D,$B12,INVENTORY!#REF!,">0")/$C12),"N/A") -> N/A
A13: POM Kitchen Tools | B13: EA | C13: =COUNTIFS(INVENTORY!D:D,B13,INVENTORY!J:J,'IN STOCK%'!A13) -> 20 | D13: =IFERROR(IF(COUNTIFS(INVENTORY!$J:$J,$A13,INVENTORY!$D:$D,$B13, INVENTORY!Q:Q,">0")/$C13=1,"",COUNTIFS(INVENTORY!$J:$J,$A13,INVENTORY!$D:$D,$B13,INVENTORY!Q:Q,">0")/$C13),"N/A") | E13: =IFERROR(IF(COUNTIFS(INVENTORY!$J:$J,$A13,INVENTORY!$D:$D,$B13, INVENTORY!#REF!,">0")/$C13=1,"",COUNTIFS(INVENTORY!$J:$J,$A13,INVENTORY!$D:$D,$B13,INVENTORY!#REF!,">0")/$C13),"N/A") -> N/A | F13: =IFERROR(IF(COUNTIFS(INVENTORY!$J:$J,$A13,INVENTORY!$D:$D,$B13, INVENTORY!#REF!,">0")/$C13=1,"",COUNTIFS(INVENTORY!$J:$J,$A13,INVENTORY!$D:$D,$B13,INVENTORY!#REF!,">0")/$C13),"N/A") -> N/A | G13: =IFERROR(IF(COUNTIFS(INVENTORY!$J:$J,$A13,INVENTORY!$D:$D,$B13, INVENTORY!#REF!,">0")/$C13=1,"",COUNTIFS(INVENTORY!$J:$J,$A13,INVENTORY!$D:$D,$B13,INVENTORY!#REF!,">0")/$C13),"N/A") -> N/A | H13: =IFERROR(IF(COUNTIFS(INVENTORY!$J:$J,$A13,INVENTORY!$D:$D,$B13, INVENTORY!#REF!,">0")/$C13=1,"",COUNTIFS(INVENTORY!$J:$J,$A13,INVENTORY!$D:$D,$B13,INVENTORY!#REF!,">0")/$C13),"N/A") -> N/A
A14: Accessories | B14: EA | C14: 27 | D14: =IFERROR(IF(COUNTIFS(INVENTORY!$J:$J,$A14,INVENTORY!$D:$D,$B14, INVENTORY!Q:Q,">0")/$C14=1,"",COUNTIFS(INVENTORY!$J:$J,$A14,INVENTORY!$D:$D,$B14,INVENTORY!Q:Q,">0")/$C14),"N/A") | E14: =IFERROR(IF(COUNTIFS(INVENTORY!$J:$J,$A14,INVENTORY!$D:$D,$B14, INVENTORY!#REF!,">0")/$C14=1,"",COUNTIFS(INVENTORY!$J:$J,$A14,INVENTORY!$D:$D,$B14,INVENTORY!#REF!,">0")/$C14),"N/A") -> N/A | F14: =IFERROR(IF(COUNTIFS(INVENTORY!$J:$J,$A14,INVENTORY!$D:$D,$B14, INVENTORY!#REF!,">0")/$C14=1,"",COUNTIFS(INVENTORY!$J:$J,$A14,INVENTORY!$D:$D,$B14,INVENTORY!#REF!,">0")/$C14),"N/A") -> N/A | G14: =IFERROR(IF(COUNTIFS(INVENTORY!$J:$J,$A14,INVENTORY!$D:$D,$B14, INVENTORY!#REF!,">0")/$C14=1,"",COUNTIFS(INVENTORY!$J:$J,$A14,INVENTORY!$D:$D,$B14,INVENTORY!#REF!,">0")/$C14),"N/A") -> N/A | H14: =IFERROR(IF(COUNTIFS(INVENTORY!$J:$J,$A14,INVENTORY!$D:$D,$B14, INVENTORY!#REF!,">0")/$C14=1,"",COUNTIFS(INVENTORY!$J:$J,$A14,INVENTORY!$D:$D,$B14,INVENTORY!#REF!,">0")/$C14),"N/A") -> N/A
A15: TreeSpirit™ | B15: EA | C15: =COUNTIFS(INVENTORY!D:D,B15,INVENTORY!J:J,'IN STOCK%'!A15) -> 47 | D15: =IFERROR(IF(COUNTIFS(INVENTORY!$J:$J,$A15,INVENTORY!$D:$D,$B15, INVENTORY!Q:Q,">0")/$C15=1,"",COUNTIFS(INVENTORY!$J:$J,$A15,INVENTORY!$D:$D,$B15,INVENTORY!Q:Q,">0")/$C15),"N/A") -> 0.78723404 | E15: =IFERROR(IF(COUNTIFS(INVENTORY!$J:$J,$A15,INVENTORY!$D:$D,$B15, INVENTORY!#REF!,">0")/$C15=1,"",COUNTIFS(INVENTORY!$J:$J,$A15,INVENTORY!$D:$D,$B15,INVENTORY!#REF!,">0")/$C15),"N/A") -> N/A | F15: =IFERROR(IF(COUNTIFS(INVENTORY!$J:$J,$A15,INVENTORY!$D:$D,$B15, INVENTORY!#REF!,">0")/$C15=1,"",COUNTIFS(INVENTORY!$J:$J,$A15,INVENTORY!$D:$D,$B15,INVENTORY!#REF!,">0")/$C15),"N/A") -> N/A | G15: =IFERROR(IF(COUNTIFS(INVENTORY!$J:$J,$A15,INVENTORY!$D:$D,$B15, INVENTORY!#REF!,">0")/$C15=1,"",COUNTIFS(INVENTORY!$J:$J,$A15,INVENTORY!$D:$D,$B15,INVENTORY!#REF!,">0")/$C15),"N/A") -> N/A | H15: =IFERROR(IF(COUNTIFS(INVENTORY!$J:$J,$A15,INVENTORY!$D:$D,$B15, INVENTORY!#REF!,">0")/$C15=1,"",COUNTIFS(INVENTORY!$J:$J,$A15,INVENTORY!$D:$D,$B15,INVENTORY!#REF!,">0")/$C15),"N/A") -> N/A
A16: M VINTAGE G-10 | B16: EA | C16: =COUNTIFS(INVENTORY!D:D,B16,INVENTORY!J:J,'IN STOCK%'!A16) -> 20 | D16: =IFERROR(IF(COUNTIFS(INVENTORY!$J:$J,$A16,INVENTORY!$D:$D,$B16, INVENTORY!Q:Q,">0")/$C16=1,"",COUNTIFS(INVENTORY!$J:$J,$A16,INVENTORY!$D:$D,$B16,INVENTORY!Q:Q,">0")/$C16),"N/A") | E16: =IFERROR(IF(COUNTIFS(INVENTORY!$J:$J,$A16,INVENTORY!$D:$D,$B16, INVENTORY!#REF!,">0")/$C16=1,"",COUNTIFS(INVENTORY!$J:$J,$A16,INVENTORY!$D:$D,$B16,INVENTORY!#REF!,">0")/$C16),"N/A") -> N/A | F16: =IFERROR(IF(COUNTIFS(INVENTORY!$J:$J,$A16,INVENTORY!$D:$D,$B16, INVENTORY!#REF!,">0")/$C16=1,"",COUNTIFS(INVENTORY!$J:$J,$A16,INVENTORY!$D:$D,$B16,INVENTORY!#REF!,">0")/$C16),"N/A") -> N/A | G16: =IFERROR(IF(COUNTIFS(INVENTORY!$J:$J,$A16,INVENTORY!$D:$D,$B16, INVENTORY!#REF!,">0")/$C16=1,"",COUNTIFS(INVENTORY!$J:$J,$A16,INVENTORY!$D:$D,$B16,INVENTORY!#REF!,">0")/$C16),"N/A") -> N/A | H16: =IFERROR(IF(COUNTIFS(INVENTORY!$J:$J,$A16,INVENTORY!$D:$D,$B16, INVENTORY!#REF!,">0")/$C16=1,"",COUNTIFS(INVENTORY!$J:$J,$A16,INVENTORY!$D:$D,$B16,INVENTORY!#REF!,">0")/$C16),"N/A") -> N/A
